Workbook

Sheet 名字规范！！！
A1: SONG | B1: LIVE
A2: 黒のバースデイ | B2: Ave Mujica 0th LIVE「Primo die in scaena」
A3: ふたつの月 ~Deep Into The Forest~ | B3: Roselia「Farbe」DAY2
A4: Choir 'S' Choir | B4: Ave Mujica 1st LIVE 「Perdere Omnia」
A5: 神さま、バカ | B5: MEGA VEGAS 2024
A6: Mas?uerade Rhapsody Re?uest | B6: Ave Mujica 2nd LIVE「Quaerere Lumina」神奈川公演
A7: Ave Mujica | B7: Ave Mujica 2nd LIVE「Quaerere Lumina」爱知公演
A8: 暗黒天国 | B8: BILIBILI MACRO LINK 2024 DAY1
A9: 堕天 | B9: BILIBILI MACRO LINK 2024 DAY2
A10: KINGS | B10: Animelo Summer Live 2024 -Stargazer-
A11: Determination Symphony | B11: Ave Mujica 3rd LIVE「Veritas」
A12: PASSIONATE ANTHEM | B12: ANIMAX MUSIX 2024 FALL
... A32: 残酷な天使のテーゼ | B32: Ave Mujica 6th LIVE 「Ulterius Procedere」 大阪公演
B33: BanG Dream! 10th Anniversary LIVE「In the name of BanG Dream!」
B34: MyGO!!!!!×Ave Mujica ツーマンライブ「“moment / memory”」
B35: MEGA VEGAS 2026
B36: CENTRAL MUSIC & ENTERTAINMENT FESTIVAL 2026
B37: BanG Dream! Special LIVE in TAIPEI DAY1 : MyGO!!!!!×Ave Mujica「"moment / memory"」
B38: Ave Mujica LIVE TOUR 2026「Exitus」福冈公演
B39: Ave Mujica LIVE TOUR 2026「Exitus」大阪公演
B40: Ave Mujica LIVE TOUR 2026「Exitus」爱知公演
B41: Ave Mujica LIVE TOUR 2026「Exitus」东京公演
B42: Ave Mujica LIVE TOUR 2026「Exitus」-FINAL- DAY1
B43: Ave Mujica LIVE TOUR 2026「Exitus」-FINAL- DAY2
B44: BEAT AX -SUMMER EDITION 2026-
... B48: SUMMER SONIC 2026 TOKYO

Sheet lyrics_atlas_rules
A1: function | B1: jp/cn | C1: terms | D1: display
A2: similar | B2: jp | C2: blue|青い|蒼き|碧い | D2: 青い
A3: similar | B3: cn | C3: blue|蓝色|蔚蓝|湛蓝 | D3: 蓝色
A4: combine | B4: jp | C4: blue world | D4: Blue World
A5: combine | B5: cn | C5: blue world | D5: Blue World
A6: exclude | B6: jp | C6: menn|mennus|taa|philis|poliaa|jealis|moliaa|let|DON'T|re
A7: exclude | B7: cn | C7: menn|mennus|taa|philis|poliaa|jealis|moliaa|let|don|re
A8: similar | B8: jp | C8: 時|時代|とき | D8: 時
A9: similar | B9: jp | C9: 天|空|天球|そら| | D9: そら
A10: exclude | B10: jp | C10: ゆく
A11: similar | B11: jp | C11: 神|神様|神さま|god | D11: 神
A12: similar | B12: jp | C12: 星|ほし | D12: 星
A13: combine | B13: jp | C13: Ave Mujica（世界） | D13: 世界
A14: combine | B14: jp | C14: 輪舞曲（ロンド） | D14: ロンド
A15: combine | B15: jp | C15: 惑星（ほし） | D15: ほし
A16: combine | B16: jp | C16: 宇宙（そら） | D16: そら
A17: combine | B17: jp | C17: 祈り人（prayer） | D17: prayer
A18: combine | B18: jp | C18: 騎士（ナイト） | D18: ナイト
A19: combine | B19: jp | C19: 運命（さだめ） | D19: さだめ
A20: combine | B20: jp | C20: 大宇宙（おおぞら） | D20: おおぞら
A21: combine | B21: jp | C21: 命（ほのお） | D21: ほのお
A22: similar | B22: jp | C22: ひと|人 | D22: 人

Sheet announcements
A1: date | B1: msg | C1: pinned
A2: 2026.08.22 | B2: 试运行 意见与建议请联系actury1995@outlook.com | C2: 1
A3: 2026.08.22 | B3: 新增导航页公告栏目 | C3: 0
A4: 2026.08.22 | B4: 1.浏览器性能优化 2.Songs更新黒のバースデイ、ふたつの月 ~Deep Into The Forest~、Choir 'S' Choir 3.日常BUG维护 | C4: 0
A5: 2026.08.23 | B5: 1.新增ico 2.Songs更新Mas?uerade Rhapsody Re?uest、神さま、バカ、Ave Mujica 3.Gallery布局优化 4.Live UI优化 5.日常BUG维护 | C5: 0
A6: 2026.08.24 | B6: 1.timeline新增倒序&按年份筛选 2.Songs更新素晴らしき世界 でも どこにもない場所 3.浏览器性能优化 4.Lyrcis 全面优化，更接近BK排版 5.Songs搜索启用，可使用花名 | C6: 0
A7: 2026.08.25 | B7: 1.Songs更新Angles，元素专歌曲占位中 2.LIVE样式更新 3.日常BUG维护 | C7: 0
A8: 2026.08.26 | B8: 1.LIVE logo样式测试 2.公告样式变更 3.interview开放&内容测试 | C8: 0
A9: 2026.08.27 | B9: 1.interview内容测试完成 新增2024/10/02 Diggy-MO'访谈 2.LIVE Backstage图片展示功能测试：SUMMER SONIC 2026 OSAKA完成 | C9: 0
A10: 2026.08.29 | B10: 1.interview更新4篇 2.songs更新元素曲歌词 3.live summer sonic 2026 backstage更新完成 4.Bug处理 | C10: 0
A11: 2026.08.30 | B11: 1.songs全歌曲基础信息&performance更新完毕 2.timeline 弄李部分更新至2024.2 3.live新增跳转切片的功能 4.Bug修复 | C11: 0
A12: 2026.08.31 | B12: 1.timeline弄李 ~2024 更新完成 2.BUG修复 | C12: 0
... A15: 2026.09.03 | B15: bug修复 | C15: 0
A16: 2026.09.06 | B16: 1.Bug修复 2.songs&lives更新 3.交互优化 4.每首歌/访谈/live提供标识码，分享时可准确定位 5.lives新增数据分析模块 | C16: 0
A17: 2026.09.07 | B17: 1.Bug修复 2.live setlist更新至上海鸡狗2 3.interview更新2023/09/15访谈后篇 4.分享链接优化 | C17: 0
A18: 2026.09.11 | B18: 1.lives新增数据分析模块优化 2.新增discography子页面，收集实体光盘信息 3.interview新增多篇原文&扫图 4.共享组件重构 | C18: 0
A19: 2026.09.14 | B19: 内容更新请见Something New推送，本板块记录公告&功能更新 | C19: 1
A20: 2026.09.14 | B20: 1.Live数据分析内容优化 2.Songs词云内容优化 | C20: 0
A21: 2026.09.15 | B21: 1.Live失效的观看链接修复

Sheet something_new
A1: content_type | B1: content_ref | C1: update_date | D1: show
A2: discography | B2: kaminonawo | C2: 46277 | D2: no
A3: discography | B3: 横k鸡狗2bd | C3: 46277 | D3: no
A4: interview | B4: Voice Febri Vol.1 杂志全员访谈 | C4: 46277 | D4: no
A5: interview | B5: 月刊ブシロード2024年2月号 杂志全员访谈 | C5: 46277 | D5: no
A6: interview | B6: 「わかれ道の、その先へ」 CONCEPT PHOTOBOOK访谈 Ave Mujica部分 | C6: 46277 | D6: no
A7: discography | B7: 鸡动画bd上卷 | C7: 46279 | D7: no
A8: discography | B8: 鸡动画bd下卷 | C8: 46279 | D8: no
A9: discography | B9: 横k鸡狗1bd | C9: 46279 | D9: no
A10: discography | B10: 3rd single | C10: 46279 | D10: no
A11: discography | B11: 完满黑胶 | C11: 46280 | D11: yes
A12: discography | B12: 梅奔鸡狗1 | C12: 46280 | D12: yes
A13: discography | B13: 精选 | C13: 46280 | D13: yes
... A15: song | B15: A Song Of Romance | C15: 46279 | D15: yes

Sheet songs
A1: song_name | B1: song_name_jp | C1: album | D1: album_year | E1: release_date | F1: cover | G1: type | H1: lyricist | I1: composer | J1: arranger | K1: first_stage | L1: mv_url | M1: lyrics_jp | N1: lyrics_cn | O1: appearances | P1: search_keywords
A2: Black Birthday | B2: 黒のバースデイ | C2: Digital Single | D2: 2023 | E2: 45026 | F2: images/黑色生日.webp | G2: Original | H2: Diggy-MO' | I2: 賀佐泰洋(SUPA LOVE) | J2: 賀佐泰洋(SUPA LOVE) | K2: Ave Mujica 0th LIVE 「Primo die in scaena」 | L2: https://www.bilibili.com/video/BV16v4y1H7ZR | M2: この領域まで侵されて そう プラットフォームは上下する\n新しく記された my バースデイ 今夜 感じて 燃え 悶える\nna, 生々しい艷やかな mad day 秘密めいた ruler loo-la, cool, cool,\n“ようこそ おいでなさい” 告げる 始まりのとき\n\nねぇ しなやかなつま先が ‘ゆらっ’描き出すわ輪舞曲(ロンド)\n純白のドレスを さあ いま 染めて闇の色\n殺める影よ 舞い上がれ\n\n見える 見える 見えないものが ほら\n生まれ変わる ああ 本当の私に\n\n\n\nエンジェル・インターセプター concept 混乱のフェーズ 堕ちる術中\nその小さな胸を引き裂いて\nbloody lover, lover, la-la-la, bloody 散らばるよ 擦り切れたフィルム\n場面 場面 蘇る 瞼の裏側で\n\nねぇ 張り付く夜には また 究極の快楽が\njack-jackie, 邪鬼 zap, zap, でもまだ 足りないよ足りない\n求めて求めて 苛まれて\n\n馳せる 馳せる 消えてゆく惑星(ほし)が ほら\n宇宙(そら)のリスク 真実を歪めたなら\n\n\n\ncallin' 呼び続けてもまだ darlin' 戻らない\n誰もが 選ばれたパズルのピースに\nこのまま このままでいい 世界をあげるわ\n\n見える 見える 見えないものが ほら\n生まれ変わる ああ 本当の私に\n\noh, my..\nblack-black, black, my black birthday | N2: 连此领域也被侵蚀 是的 舞台升起降下\n被重新记载的 my 诞生日 今晚 去感受 燃烧着 痛苦挣扎\nna, 鲜活妖艳的 mad day 充斥秘密的 ruler loo-la, cool, cool, \n“欢迎前来 请过来这里” 宣告着 起始之时刻\n\n呐啊 柔软优美的足尖 摇荡勾勒轮舞曲\n将那纯白的礼服 来吧 此刻 染上黑暗之色\n杀戮的暗影啊 升腾而起吧 \n\n看见了 看见了 本不可见之物 看啊\n重获新生 啊啊 成为真正的我\n\n\n\n天使拦截者 concept 混乱的局面 堕入陷阱之中\n将那小小的胸膛撕裂\nbloody lover, lover, la-la-la, bloody 散落一地啊 磨损的胶片\n一幕幕场景 重新浮现 在眼帘之后\n\n呐啊 在这黏着不去的夜里 再一次 极致的快感…\njack-jackie, 邪鬼 zap, zap, 但还不够啊 还远远不够啊\n追求着渴望着 被折磨着\n\n奔驰着 奔驰着 逐渐消逝的行星 看啊\n若要扭曲真实 则将承受宇宙的风险\n\n\n\ncallin' 即使不断呼喊 darlin' 也不会回来\n无论是谁 都会被选中成为拼图的碎片\n这样就好 维持这样就好 我会给你整个世界\n\n看见了 看见了 本不可见之物 看啊\n重获新生 啊啊 成为真正的我\n\noh, my..\nblack-black, black, my black birthday | O2: Alea jacta est,Ave Música | P2: 黑色生日，黑生
A3: Two Moons | B3: ふたつの月 ~Deep Into The Forest~ | C3: Digital Single | D3: 2023 | E3: 45032 | F3: images/双月.webp | G3: Original | H3: Diggy-MO' | I3: 長谷川大介(SUPA LOVE) | J3: 長谷川大介(SUPA LOVE) | K3: Ave Mujica 0th LIVE 「Primo die in scaena」 | L3: https://www.bilibili.com/video/BV1vs4y127DJ | M3: ああ 深く 深く 迷い込んだ森で\nなぜか私を開いて壊すもの そう そして 感じさせるもの\n木から落ちる leaf に ほらいま 映り込む未来\n\nこの風 吹き抜けるとき 私は祈り人(prayer)\n\nおしえてよ おしえてよ こんなに美しいのはなぜ\n惹かれてく 堕ちてく 月が笑う夜\n\n\n\n銀のトレーにフルーツを キャンドルホルダーに火を\nこのまま いくつかの意味をさがすの その幻を暴きたい\n常に終わりは始まりと組まれる 不思議な creation\n\nこの風 命集めて いま 昇るなら\n\nおしえてよ おしえてよ こんなに苦しいのはなぜ\n鏡の中の彼女が 嘲笑う夜\n\n\n\n大気の重さで もうひとつの月が顔を出す\n“早く目覚めて ここで眠ってしまわないように”\n\nおしえてよ おしえてよ こんなに美しいのはなぜ\n惹かれてく 堕ちてく 月が笑う夜 | N3: 啊啊 深深地 深深地 迷失在森林中\n某物莫名将我剖开破坏 是啊 而后又让我有所感受\n从树上落下的 leaf 上 看吧 此刻 正映照着未来\n\n当这阵风吹过时 我即是祈祷者（prayer）\n\n请告诉我 请告诉我吧 为何如此美丽动人\n渐受蛊惑 步步坠落 月亮嗤笑之夜\n\n\n\n将果实盛入银盘 为烛台点燃火焰\n就这样 寻找种种意义 渴望揭穿那重幻象\n结束总与开始交织纠缠 不可思议的 creation\n\n这阵风 汇聚生命 现在 若能升腾而起\n\n请告诉我 请告诉我吧 为何如此痛苦难耐\n镜中的她 嘲弄之夜\n\n\n\n大气的重压之下 另一轮月亮显露真容\n“快快醒来 可不要在此处沉睡”\n\n请告诉我 请告诉我吧 为何如此美丽动人\n渐受蛊惑 步步坠落 月亮嗤笑之夜 | O3: Alea jacta est | P3: 双月
A4: Choir 'S' Choir | B4: Choir 'S' Choir | C4: Digital Single | D4: 2023 | E4: 45039 | F4: images/CSC.webp | G4: Original | H4: Diggy-MO' | I4: 角本麻衣(SUPA LOVE) | J4: 角本麻衣(SUPA LOVE) | K4: Ave Mujica 0th LIVE 「Primo die in scaena」 | L4: https://www.bilibili.com/video/BV1Xg4y1j7Lt | M4: [daa-mennus, daa-menn, philis-poliaa, taa-mennus, taa-menn, jealis-moliaa]\n\nChoir Choir, Choir Choir ‘S’ Choir\n\n\n\nそう サジェスチョンなら Spade 彷徨うスペクター [Spiritual, So Spiritual]\nイミテーションやら聖なる讃美歌 [Sensual, So Sensual]\nサディスティック サディスティック 堕天使\nヒステリック ヒステリック 宿る刻\n[look, 歌う胸像 the show must go on ルカ 精霊 精霊 ghost, oh, it's comin']\n\n‘信じる？ 信じない？’ いないいないばあ\n感情の万華鏡 引きずり込むのは\n\nねぇ誰？ ねぇ誰？ 叫ぶ声が\n夜に酔えば 真っ赤に腫れた唇がわたしを貪るの\n‘S’ カレート ‘S’ カレート 忍び寄るわ mysterious\n目眩く描くほどに 狂い咲くカーニヴァル\n\nChoir Choir, Choir Choir ‘S’ Choir\n\n\n\noh, イリュージョンなら左手のジェスチャー [Spiritual, So Spiritual]\nテンプテーション 神話にはつづきが [Sensual, So Sensual]\nサタニック サタニック マジェスティ\nヒプノティック ヒプノティック 裁く刻\n[see, 'il giudizio, la giustizia' 下る極彩色 shockin' psychic]\n\n‘感じる？ 感じない？’ お気に召す mo'\n触れてみて 触れてみて 試されてもいい\n\nねぇ誰？ ねぇ誰？ 甘い夢が\n闇に占う カードの悪魔 誘う魂の行方 今\n‘S’ カレート ‘S’ カレート 気の触れた my desire\n鼓膜を劈くほどに 咽び泣くアリア\n\n\n\n[daa-mennus, daa-menn, philis-poliaa, taa-mennus, taa-menn, jealis-moliaa,\ndaa-mennus, daa-menn, philis-poliaa, daa-la-la-daa-daa]\n\nああ ワルツに身を委ねて ゆらゆらゆら\n\n\n\n誰？ ねぇ誰？ 叫ぶ声が\n夜に酔えば 真っ赤に腫れた唇がわたしを貪るの\n‘S’ カレート ‘S’ カレート 忍び寄るわ mysterious\n目眩く描くほどに 狂い咲くカーニヴァル\n\n\n\n[daa-mennus, daa-menn, philis-poliaa, taa-mennus, taa-menn, jealis-moliaa,\ndaa-mennus, daa-menn, philis-poliaa, taa-mennus, taa-menn, jealis-moliaa]\n\nChoir Choir, Choir Choir ‘S’ Choir | N4: [daa-mennus, daa-menn, philis-poliaa, taa-mennus, taa-menn, jealis-moliaa]\n\nChoir Choir, Choir Choir ‘S’ Choir\n\n\n\n是的 若要给出暗示 Spade 彷徨的幽灵 [Spiritual, So Spiritual]\n赝品亦或是神圣的赞美歌 [Sensual, So Sensual]\n嗜虐的 嗜虐的 堕天使\n癔病的 癔病的 附身之时\n[look, 歌唱的胸像 the show must go on 路加 精灵 精灵 ghost, oh, it's comin']\n\n‘相信？ 不相信’ 不在、不在、在这里\n感情的万华镜 被卷入其中的是\n\n是谁？ 是谁？ 是谁正在呼喊\n沉醉于夜晚 鲜红肿胀的嘴唇将我贪婪吞噬\n‘S’calate ‘S’calate 悄然接近的 mysterious\n勾勒到目眩神迷 癫狂盛放的狂欢\n\nChoir Choir, Choir Choir ‘S’ Choir\n\n\n\noh, 若是幻觉则用左手的手势 [Spiritual, So Spiritual]\n诱惑 神话仍未终结 [Sensual, So Sensual]\n恶魔般的 恶魔般的 无上威严\n催眠的 催眠的 裁决之时\n[see, 'il giudizio, la giustizia' 降临的绚丽色彩 shockin' psychic]\n\n‘感觉到？ 感觉不到？’如你所愿 mo'\n试着触摸 试着触摸 即使受到考验也无妨\n\n是谁？ 是谁？ 将这甜美的梦…\n向黑暗问卜 卡牌的恶魔 引诱灵魂的去向 此刻\n‘S’calate ‘S’calate 陷入疯狂的 my desire\n似要刺破鼓膜一般 呜咽的咏叹调\n\n\n\n[daa-mennus, daa-menn, philis-poliaa, taa-mennus, taa-menn, jealis-moliaa,\ndaa-mennus, daa-menn, philis-poliaa, daa-la-la-daa-daa]\n\n啊啊 委身于华尔兹吧 摇摇晃晃\n\n\n\n是谁？ 是谁？ 是谁正在呼喊\n沉醉于夜晚 鲜红肿胀的嘴唇将我贪婪吞噬\n‘S’calate ‘S’calate 悄然接近的 mysterious\n勾勒到目眩神迷 癫狂盛放的狂欢\n\n\n\n[daa-mennus, daa-menn, philis-poliaa, taa-mennus, taa-menn, jealis-moliaa,\ndaa-mennus, daa-menn, philis-poliaa, taa-mennus, taa-menn, jealis-moliaa]\n\nChoir Choir, Choir Choir ‘S’ Choir | O4: Alea jacta est,Ave Música | P4: csc，合唱团，合唱班
A5: Memento Mori | B5: 神さま、バカ | C5: Digital Single | D5: 2023 | E5: 45053 | F5: images/神蠢.webp | G5: Original | H5: Diggy-MO' | I5: 槇島隆人(SUPA LOVE) | J5: 槇島隆人(SUPA LOVE) | K5: Ave Mujica 0th LIVE 「Primo die in scaena」 | L5: https://www.bilibili.com/video/BV1Ss4y137ML | M5: 在るようで無いのか はたまたその逆か 戻れぬゲームにぼくらはいる\n歪な概念が漂うこの空は 所詮 選択の連続なのさ\n\n理不尽な剣を振りかざす騎士(ナイト)たち\nなぜに闘うの 誰のために\n\nわからない わかっちゃいない ぼくら きっとなにひとつ\n愛と接吻が壊したら ねぇ なにを恨めばいいの\n神さま、バカ\n\n\n\n信じる理由が欲しいだけなのに また何かを探り合っている\n進もうとする者 そして留まる者 それぞれの正義 運命(さだめ) コイントス\n\n誰もが皆 生まれるために死ぬのかな\n嗚呼 ただ救われたいよ\n\nわからない わかっちゃいない ぼくら きっとなにひとつ\n空が哀しみに染まるなら 白い百合の花を浮かべて\n弔うから\n\n\n\nだから せめて きかせて\nねぇ お願い もう一度\n\nわからない わかっちゃいない ぼくら きっとなにひとつ\n愛と接吻が壊したら ねぇ なにを恨めばいいの\n神さま、バカ | N5: 似有还无 亦或是相反 我们身陷无法回头的 游戏中\n漂浮着扭曲概念的这片天空 终究只是选择的连续\n\n高举荒谬之剑的骑士们\n为何而战 为谁而战\n\n不明白 根本不明白 我们必定是一无所知\n若爱与吻将一切摧毁 呐 我又该去憎恨什么\n神啊 愚蠢\n\n\n\n明明只是想要相信的理由 却又在相互试探着什么\n试图前行之人 以及停留之人 各自的正义 命运 抛掷硬币\n\n难道所有人都是为了诞生而死去吗\n啊啊 只是想要被拯救啊\n\n不明白 根本不明白 我们必定是一无所知\n若天空浸染悲哀 便让纯白的百合花浮起\n以此悼念\n\n\n\n所以 至少 让我听见\n呐啊 拜托你 请再一次\n\n不明白 根本不明白 我们必定是一无所知\n若爱与吻将一切摧毁 呐 我又该去憎恨什么\n神啊 愚蠢 | O5: Alea jacta est | P5: 愚神，神蠢，神八嘎，神明笨蛋
A6: Mas?uerade Rhapsody Re?uest | B6: Mas?uerade Rhapsody Re?uest | C6: Digital Single | D6: 2023 | E6: 45067 | F6: images/MRR.webp | G6: Original | H6: Diggy-MO' | I6: あらケン(SUPA LOVE) | J6: あらケン(SUPA LOVE) | K6: Ave Mujica 0th LIVE 「Primo die in scaena」 | L6: https://www.bilibili.com/video/BV13g4y1c743 | M6: なら もう汚れたっていい 重い微睡みに身を委ねて\nMas?ueradeその仮面の意味don't be afraid私は贈り物\n紫の空 召されて\n\n\n\n戯れる影と影 飲み込まれ さんざめく狂気さえ 心地良いのか\n滑り込む 夢 夢[the point of no return, dreamin',dreamin',]\n導いてよtake me thereoh yes,oh yes,\n捧げるわ いま\n\nああ もうどうだっていい 秘めやかな想いが抉じ開けて\nMas?uerade 終わらないラプソディ ぬるい吐息が奏でる\nやけに甘い調べに抱かれて\n\n\n\n狂おしい悦びは 何故に何故 蝕んでく世界線 脈を打つ\n紫煙 燻らす指[the point of no return, dreamin',dreamin',]\n天使になれない\n\nなら もう汚れたっていい 重い微睡みに身を委ねて\nMas?ueradeその仮面の意味don't be afraid私は贈り物\n紫の空 召されて\n\n\n\nああ もうどうだっていい 秘めやかな想いが抉じ開けて\nMas?uerade 終わらないラプソディ ぬるい吐息が奏でる\nやけに甘い調べに抱かれて | N6: 那么 即使染上污秽也无妨 委身于沉重的浅眠\nMas?uerade 那副面具的意义 don't be afraid 我是赠礼\n紫天 蒙召而去\n\n\n\n嬉戏的影与影 被吞噬殆尽 哪怕是喧腾的狂气 竟也感到愉快吗\n滑入梦中 梦 梦 [the point of no return, dreamin', dreamin',]\n引导我吧take me there oh yes, oh yes,\n此刻 献出一切\n\n啊啊 怎样都已无所谓了 隐秘的心绪被强行撬开\nMas?uerade 温热的吐息奏响永不终结的狂想曲\n被那异常甜美的旋律拥入怀中\n\n\n\n令人发狂的欢愉 究竟为何 为何 不断侵蚀世界线 脉搏跳动\n紫烟 萦绕指尖[the point of no return, dreamin',dreamin',]\n无法成为天使\n\n那么 即使染上污秽也无妨 委身于沉重的浅眠\nMas?uerade 那副面具的意义 don't be afraid 我是赠礼\n紫天 蒙召而去\n\n\n\n啊啊 怎样都已无所谓了 隐秘的心绪被强行撬开\nMas?uerade 温热的吐息奏响永不终结的狂想曲\n被那异常甜美的旋律拥入怀中 | O6: Alea jacta est | P6: 假面舞会，mas
A7: Ave Mujica | B7: Ave Mujica | C7: Ave Mujica 0th LIVE 「Primo die in scaena」现场表演 | D7: 2023 | E7: 45081 | F7: images/同名.webp | G7: Original | H7: 上松範康(Elements Garden) 織田あすか(Elements Garden) | I7: 上松範康(Elements Garden) | J7: 藤間仁(Elements Garden) | K7: Ave Mujica 0th LIVE 「Primo die in scaena」 | L7: https://www.bilibili.com/video/BV1MP411h759 | M7: 「…ようこそ。Ave Mujicaの世界へ」\n\n不可逆な生命の歴史 - あらすじ - へと\n終焉の杭を打つの\n首を傾げコクリと愛想笑う\n道化 - ドール -たちが紡ぐ物語 - ストーリー-\n\n三日月の舟で（ら La ラ R ァ羅rA乱）\n音楽の花を（ら La ラ R ァ裸rA嵐）\n千切ってはお星に変えて\n毒してあげる\n(Memento mori) 呪縛なの？\n(Memento mori) 救済なの？\n(此処に) 心、闇に捧げよ…！\n\nAve Musica…奇跡を日常に(Fortuna)\nAve Musica…慈悲を与えましょう(Lacrima)\nこの右手あなたが掴むなら (果てなき)\n漆黒の (魅惑に) 悦楽の (虜に)\nŌ…宿命は産声を上げる\n\n心臓と戯れた喜びから\n感じたのは生の息吹\n今宵も心地よく深淵を揺らし\nあなたごと引き摺り込んでく\n\n秘密を導に（ら La ラ R ァ羅rA乱）\n甘美な呪文が（ら La ラ R ァ裸rA嵐）\n荊棘のように絡みついて\n離さないと言う\n(Memento mori) 躍るように\n(Memento mori) 贖うように\n(此処で) 歌と結ばれましょう\n\nAve Musica…仮面の民は誘う \nAve Musica…安らかな世界へ \nあなたの過去を差し出すのなら (必ず)\nいかなる (願いも) いかなる (望みも)\nSic…叶えてあげる\n\nAve Musica…堕ちて、堕ちてゆくの(Fortuna)\nAve Musica…戻れない所まで(Lacrima)\n大丈夫 何も怖くないわ (委ねて)\n始めよう (永遠を) あなたと (私の)\n\nAve Musica…奇跡を日常に(Fortuna)\nAve Musica…慈悲を与えましょう(Lacrima)\nこの右手あなたが掴むなら (果てなき)\n漆黒の (魅惑に) 悦楽の (虜に)\nŌ…宿命は産声を上げる | N7: 「…欢迎来到 Ave Mujica的世界」\n\n向着不可逆的生命历史 - 概要 -\n钉下终焉之桩\n歪头 轻颔 应酬般地笑\n小丑 - 人偶 -们所编织的故事 - Story -\n\n乘着新月之舟（ら La ラ R ァ羅rA乱）\n将音乐之花（ら La ラ R ァ裸rA嵐）\n一片片撕碎化为星星\n令你染上剧毒\n（Memento mori）是咒缚吗？\n（Memento mori）是救赎吗？\n（在此）把心灵奉献给黑暗吧…！\n\nAve Musica…将奇迹化为日常（Fortuna）\nAve Musica…将慈悲赐予你们 (Lacrima)\n若你紧握住这只右手（永无止尽）\n染上漆黑的（魅惑） 成为欢愉的（俘虏）\nŌ…宿命发出初啼\n\n从与心脏嬉戏的喜悦中\n感受到的是生之气息\n今夜亦惬意地摇撼深渊\n连同你一并拖入其中\n\n以秘密为指引（ら La ラ R ァ羅rA乱）\n那甜美的咒文（ら La ラ R ァ裸rA嵐）\n如同荆棘般紧紧缠绕\n宣告着决不放开\n（Memento mori）如跃动般\n（Memento mori）如赎罪般\n（在此）与歌结为一体吧\n\n(Fortuna)Ave Musica…假面之民在诱惑（Fortuna）\n(Lacrima)AveMusica…前往安宁的世界（Lacrima）\n若你愿意献上过去 那么（必定）\n无论怎样的（愿望） 无论怎样的（希求）\nSic…都将为你实现\n\nAve Musica…坠落，不断坠落 (Fortuna)\nAve Musica…直至那不归之处（Lacrima）\n没关系 不需要恐惧（委身吧）\n开始吧（永恒）你（与我）的\n\nAve Musica…将奇迹化为日常（Fortuna）\nAve Musica…将慈悲赐予你们 (Lacrima)\n若你紧握住这只右手（永无止尽）\n染上漆黑的（魅惑） 成为欢愉的（俘虏）\nŌ…宿命发出初啼 | O7: Alea jacta est | P7: 同名
A8: Ankoku Tengoku | B8: 暗黒天国 | C8: Ave Mujica 0th LIVE 「Primo die in scaena」现场表演 | D8: 2023 | E8: 45081 | F8: images/暗黑天国.webp | G8: Cover | H8: 宝野アリカ | I8: 片倉三起也 | J8: UYKADO | K8: Ave Mujica 0th LIVE 「Primo die in scaena」 | M8: Darling 目を開けて \nこの世の悪の巣窟で 啄まれる心を頂戴\n逃げもできぬ 幽閉の蒼白の王子よ\nわたしが女神\nバタフライの羽も 天使の唾液も\nあなたをまだ見ぬ極楽へ 連れ出せはしない\n腐りかけた自由 垢に塗れた愛\n煉獄の焔でzeroから済世しましょう\n不夜の空に黒いダリア\n失する妄想 堕ちる現実\nもがけ蟻ジゴク\nDarling 声上げて このいま刺し違えるほど\n大事なものが欲ししのなら 祈りは果てて\n牢獄で昇天の姫君 あなたが魔王\n怒りの拳も嘆きの傷も跡形もなく\n熔けて消えて散って泡沫\nすべては密猟区 埋もれた罠に ハメられるのなら\n粉々に砕いてほしいわ\n死に至らぬ病 心臓には毒薬\n冒されながらも生きる日々 祝福されたし\n眼蓋の奥 赤いザクロ\n恋する右脳 臆する左脳\nつぶせ針の山\nHoney 抱きしめて\n素肌の絹の光沢で 恍惚しちゃう時間を頂戴\nカラダは裂けて 天国で再会の片割れ\nふたりは半神\n至極の善と魅惑の奈落\n約束の地は 何所か其所か夢かうつつか\nサアドウゾ 此処イラデ 絶頂ヲ迎エマショウ\nDarling 目を開けて\nこの世の悪の巣窟を 蝕めない心を頂戴\n逃げもしない 幽閉の蒼白の王子よ\nわたしが女神\nDarling 声上げて このいま刺し違えるほど\n大事なものが欲しいのなら 祈りは果てて\n牢獄で昇天の姫君 あなたが魔王\n組まれた指と懺悔の首と贖う罪は\n何か何れか嘘か真か | N8: 亲爱的 睁开眼睛吧 \n在这世间邪恶的巢穴中 让我取走你那被啄食的心灵\n无法逃离 被幽禁的苍白王子啊\n我就是女神\n蝴蝶的翅膀 天使的唾液\n都不会把你带往 未曾见过的极乐世界\n腐朽的自由 被污垢涂盖的爱\n就用炼狱之焰 从零开始拯救这世间吧\n不眠的天空中 黑色的大丽花\n丧失的妄想 堕落的现实 \n挣扎吧 犹如无法摆脱的蚁狱\n亲爱的 放声呼喊吧 在这个要同归于尽的当下\n假若你渴望珍贵之物 祈祷便是尽头\n牢狱中升天的公主 你才是魔王\n愤怒的拳头 哀叹的伤痕 终将无迹可寻\n熔化 消散 化作泡沫\n一切都是非法狩猎场 要是被落入深埋的陷阱中\n那就请将我彻底粉碎吧\n无法致死的疾病 对心脏不过是毒药\n虽然被侵袭但仍存活的日子 要受到祝福吗\n眼睑深处 红色的石榴 \n恋爱的右脑 胆怯的左脑 \n压碎它吧 犹如针山之刑\n亲爱的 紧紧相拥吧\n用光滑如绸缎的肌肤 赐予我沉醉的时光\n身躯即便被撕裂 仍在天国中与另一半重逢\n我们互为半神\n至高无上的善 与魅惑的深渊\n约定之地究竟在哪 是梦境还是现实\n那么请吧 就在此处 迎来绝顶的快感\n亲爱的 睁开眼睛吧\n在这世间邪恶的巢穴中 让我吞噬你那无法侵蚀的心灵\n无法逃离 被幽禁的苍白王子啊\n我就是女神\n亲爱的 放声呼喊吧 在这个要同归于尽的当下\n假若你渴望珍贵之物 祈祷便是尽头\n牢狱中升天的公主 你才是魔王\n紧扣的指尖 忏悔的头颅 所赎的罪孽\n究竟是什么 是谎言还是事实 | O8: 「バンドリ！カバーコレクション Extra Volume」 | P8: 暗黑天国
A9: Daten | B9: 堕天 | C9: Ave Mujica 0th LIVE 「Primo die in scaena」现场表演 | D9: 2023 | E9: 45081 | F9: images/堕天.webp | G9: Cover | H9: R-指定 | I9: DJ松永 | J9: UYKADO | K9: Ave Mujica 0th LIVE 「Primo die in scaena」 | M9: あの日林檎の木の下共犯で 踏み越えてみた境界線\nすぐにblack out「あ お怒りで」\n追い立てられてこんな次元へ\n俺とした事が 俺如きですら\n俺に限っていや まさかね\n君のせいにした\n秘密を手にした\nイチジクの葉が右左\nあっという間 目が醒める かと思えば空に落ちて行く\nなんというか やめられぬ\nもうひと齧りagain\nFallin' falling 螺旋状に堕ちてゆく摩天楼に \n今 fallin' falling\n二人ぼっち 気づかない カ一テンコ一ルにも\n(Yeah yeah yeah yeah yeah)どこまでも\n(Yeah yeah yeah yeah yeah)この身任せて\nいつの間に傷が埋まってくyeah \nそこじゃ何から何までごった煮で \n鬼も仏もおんなじ目 \n全てshut out どうかしてる?\n俺らハナから大真面目\nふりほどいて来た うしろ指ですら\nむしろ追い風さ まだ足んねぇ\n蛇に睨まれた 歴史の徒花\nエデンにはまだ「空室あり」\nあっという間 染められる かと思えば熱が醒めていく\nちょっと待ってその前に\nもうひと雫 again\nFallin' falling 螺旋状に堕ちてゆく摩天楼に \n今 fallin' falling\n二人ぼっち 気づかない カ一テンコ一ルにも\n(Yeah yeah yeah yeah yeah)どこまでも \n(Yeah yeah yeah yeah yeah)この身任せて\nいつの間に傷が埋まってくyeah\nAgain fallin' falling 螺旋状に堕ちてゆく摩天楼に \n今 fallin' falling \n二人ぼっち 気づかない カ一テンコ一ルにも\n(Yeah yeah yeah yeah yeah)どこまでも \n(Yeah yeah yeah yeah yeah)この身任せて\nいつの間に傷が埋まってく\nこの血が冷めないうちに 飲み干して\n眩暈するほど気取って\n取り留めない出会いに色付けて\nこの目が醒めないうちに 憑り込んで\n狭い空ごと突き抜けてfalling\n蜜の味二人ハマってくyeah | N9: 那一天在苹果树下 你我作为共犯 跨越了那条边界线\n随即失去意识“啊 生气了呢”\n被驱逐到这片次元\n我在做什么啊 就连像我这样\n只对我一人 不对 不会吧喂\n都怪你\n掌握了秘密\n无花果叶左右颠倒\n一转眼间 才刚刚苏醒 便即将坠入空中\n怎样形容呢 让人欲罢不能\n那就再咬一口 again\nFallin' falling 在螺旋下坠的摩天楼中\n此刻坠落 坠落\n我们只有彼此 甚至未曾察觉 落幕的掌声已然响起\n(Yeah yeah yeah yeah yeah)无尽地坠落\n(Yeah yeah yeah yeah yeah)任凭这身躯飘荡\n不知不觉 伤口逐渐深埋 yeah \n那里将任意一切都炖成大杂烩\n恶鬼与神佛皆为同样的眼神 \n将一切拒之门外 你是疯了吗？\n可我们从来就是一本正经\n甩开枷锁吧 就连身后的指责\n反倒让我们乘风而行 还远远不够\n毒蛇虎视眈眈 历史徒有其表\n伊甸园仍有“空房间”\n转眼之间 脸才被染得通红 热情又即刻冷却殆尽\n请等一下 在此之前\n再给一滴甘霖 again\nFallin' falling 在螺旋下坠的摩天楼中\n此刻坠落 坠落\n我们只有彼此 甚至未曾察觉 落幕的掌声已然响起\n(Yeah yeah yeah yeah yeah)无尽地坠落\n(Yeah yeah yeah yeah yeah)任凭这身躯飘荡\n不知不觉 伤口逐渐深埋 yeah\nFallin' falling 在螺旋下坠的摩天楼中\n此刻坠落 坠落 \n我们只有彼此 甚至未曾察觉 落幕的掌声已然响起\n(Yeah yeah yeah yeah yeah)无尽地坠落\n(Yeah yeah yeah yeah yeah)任凭这身躯飘荡\n不知不觉 伤口逐渐深埋\n趁血液尚未冷却 一饮而尽\n装腔作势至头晕目眩\n为不得要领的相逢染上色彩\n趁意识尚未苏醒 互为依凭\n连带狭小的天空 穿透云霄falling\n两人一同沉浸于甜蜜的滋味yeah | O9: 「バンドリ！カバーコレクション Extra Volume」
A10: KINGS | B10: KINGS | C10: Ave Mujica 0th LIVE 「Primo die in scaena」现场表演 | D10: 2023 | E10: 45081 | F10: images/kings.webp | G10: Cover | H10: atsuko | I10: atsuko • KATSU | J10: UYKADO | K10: Ave Mujica 0th LIVE 「Primo die in scaena」 | M10: Worries slowly come and kiss\nTell me what's your name\nまた惹かれ合っては 比べ合う事でけなして\n何度夜が巡ろうとも 真っ暗闇のどっかで\n欠けた自分のpieceだったら\nSearch and kiss and destroy\nBig bang\n野蛮な情熱 冷静な衝突\n血を見るまで容赦はしないの? \nBig bang\n確かめたい 繋がっていたい 本当は恐いの?\n未完成な愛をぐっと振りかざして\n分かりたい分からない 分からず屋\n相反する正義に集う輩さ\n一瞬の安らぎに寄り添って\n似てると言われる程 気になって仕方なくなる\n目をそらしたら負けさ 未来はあやふやで\n過去は二度と変えられないと\n知っているさ\nSearch and kiss and destroy \nBig wave \n歪んだ衝動 歯痒い残響\nゆさぶってんの? 逃げたりはしない\nBig wave\n競い合っていたい 高ぶっていたい 本当は恐いの?\n不格好な愛さえ歴史の中じゃ 瞬き以下の瞬刻だろう\n舐め合う為の傷なんて無いさ\nプライドがあっち側で笑ってる \nWorries slowly come and kiss \nTell me what's your name \nWorries slowly come and kiss \nSearch and kiss and destroy \nBig bang\n野蛮な情熱 冷静な衝突\n血を見るまで容赦はしないの? \nBig bang\n確かめたい 繋がっていたい 本当は恐いの?\n未完成な愛をぐっと振りかざして\n分かりたい分からない 分からず屋\n相反する正義に集う輩さ\n一瞬の安らぎに寄り添って \nCan I feel can you feel\nLife is a moment\n惰性を打破して抱きしめたい\n舐め合う為の傷なんて無いさ\nプライドがあっち側で笑ってる | N10: 忧虑缓缓而至 轻轻吻上\n告诉我 你的名字是什么\n彼此再次相互吸引 却又因互相比较而暗自贬低\n无论要经历多少长夜 黑暗都会存在于某处\n假若缺失自己的碎片\n那就去搜寻 去亲吻 去毁坏\n大爆炸\n野蛮的热情 冷静的冲突 \n直至见血之前 都不会宽恕对方丝毫吗？\n大爆炸\n渴望得到确认 渴望得到羁绊 其实是出于恐惧吗？\n标榜着尚未完成的爱\n渴望理解 却未曾理解 不曾明白的人\n聚集在相反正义之下的人们啊\n依偎在一瞬的安宁之中\n越是被人说相似 越是在意得耿耿于怀\n移开视线便会败北 未来暧昧不清\n而过去无法再度改变\n我明明早已深知\n那就去搜寻 去亲吻 去毁坏\n掀起巨浪\n扭曲的冲动 令人焦躁的余韵\n是要让人动摇吗？我绝不会逃避的\n掀起巨浪\n渴望着竞争 渴望着兴奋 其实是出于恐惧吗？\n再笨拙的爱在历史的洪流中 不过是转瞬即逝的刹那吧\n伤痕并不是为了互相舔舐而存在\n否则自尊心会那一边冷冷嘲笑\n忧虑缓缓而至 轻轻吻上\n告诉我 你的名字是什么\n忧虑缓缓而至 轻轻吻上\n去搜寻 去亲吻 去毁坏\n大爆炸\n野蛮的热情 冷静的冲突 \n直至见血之前 都不会宽恕对方丝毫吗？\n大爆炸\n渴望得到确认 渴望得到羁绊 其实是出于恐惧吗？\n标榜着尚未完成的爱\n渴望理解 却未曾理解 不曾明白的人\n聚集在相反正义之下的人们啊\n依偎在一瞬的安宁之中\n我可感觉到 你可感觉到吗\n生命只是一瞬\n希望打破惰性 紧紧相拥\n伤痕并不是为了互相舔舐而存在\n否则自尊心会那一边冷冷嘲笑 | O10: 「バンドリ！カバーコレクション Extra Volume」
A11: Determination Symphony | B11: Determination Symphony | C11: Ave Mujica 0th LIVE 「Primo die in scaena」现场表演 | D11: 2023 | E11: 45081 | F11: images/logo/DS.webp | G11: Cover | H11: 織田あすか(Elements Garden) | I11: 藤永龍太郎(Elements Garden) | J11: 藤永龍太郎(Elements Garden) | K11: Ave Mujica 0th LIVE 「Primo die in scaena」 | M11: 潤んだ予感はbye now\n滴る痛みの中 雨色に染まって\n大きく開(ひら)いたdistance\nいつの間にか落ちてゆくわ…冷たさに\n滲んだ【スコア】探す【答え】\n降り止まない苦しみに差し出された\n微笑みの【微笑みの】Umbrella【Umbrella】\nus…包み込んで 合わさるprecious\n【Where there is a will, there is a way.】\n【Where there is a will…】\nBring it on down\n決意の調べ【hang in there】\n勇気の祈りを音色に載せて【get over】\n約束繋ぐ指先で弾(はじ)くの\nいつしか【響け】貴方の横で\n今はまだ無理でも\n【向き合う定めよ】【\nワタシハ ヤメナイ\n蜃気楼のようでfleeting\n淀んだ景色が行く 伏し目がちになって\n静けさ返ってはdistance\n声も届かずに散りだす はらはらと\n水面に映る美しき縁(えにし)は\n【the naked truth】\n誇りを 今に取り戻すわ\nBring it on down\n使命の調べ【set you free】\n折れないリビドー音色に載せて【till the end】\n約束繋ぐ指先で弾(はじ)くの\nいつしか【光れ】貴方の横で\n此れで終わりじゃない\n【奇跡はなくとも】\nワタシハ カナデル\nセカイデ ヒトツノ タイセツナヒト\nツナゲ ココロ フカク\nツナゲ ユメヲ シナヤカニ…\n涙の【スコア】映る【答え】\n降りしきった悲しみを迎えたのは\n微笑みの【微笑みの】Umbrella【Umbrella】\nus…見守るように 優しくhold on\n【Where there is a will, there is a way.】\n【Where there is a will…】\nBring it on down\n決意の調べ【hang in there】\n勇気の祈りを音色に載せて【get over】\n約束繋ぐ指先で弾(はじ)くの\nいつしか【響け】貴方の横で\n今はまだ無理でも\n【向き合う定めよ】\nワタシヨ ツキススメ…！ | N11: 暗中预感着会在此刻别离\n那份不停的痛苦 把雨水的颜色尽染\n逐渐拉开的那份距离\n不知不觉间开始落下的雨啊…如此寒冷\n铭记于心的【乐谱】寻找着【回答】\n向无尽的痛苦之雨中递来的是\n浮现微笑的【浮现微笑的】雨伞【雨伞】\n将我们…相互包裹 合而为一的珍贵之物\n【只要心中所向，道路就在前方。】\n【有志者事竟成…】\n随心所欲 将其击溃\n下定决心的旋律【坚持下去】\n将勇气的祈愿附在音色之中【将其克服】\n用那约定相连的指尖弹起\n不知不觉【奏响吧】就在你身旁奏响的\n即使是还无法实现\n面对于你的命运啊】\n我也绝对 不会放弃\n像海市蜃楼一般 转瞬即逝\n模糊的景色散去 低头是空无一物\n静止不动的那份距离\n在话语也传达不到的地方开始 簌簌地落下\n水面上倒映出的美好的缘分\n【浮现的真实】\n将骄傲 于此时去取回吧\n不再被束缚 将其击溃\n怀有使命的旋律【重夺自由】\n将不屈的本能附在音色之中【直至终结】\n用那约定相连的指尖弹起\n不知不觉【闪耀吧】就在你身旁闪耀的\n这还不是结束之时\n【即使没有什么奇迹】\n我也仍会 将其奏响\n世界上的 唯有一个 无比而珍贵的人\n相连吧 将心灵 紧紧地\n相连吧 将梦想 用那份温柔…\n泪水的【乐谱】映出着【回答】\n在无尽的悲伤之雨中迎接着的\n浮现微笑的【浮现微笑的】雨伞【雨伞】\n将我们…守护一般 用那温柔让我们向前\n【只要心中所向，道路就在前方。】\n【有志者事竟成…】\n随心所欲 将其击溃\n下定决心的旋律【坚持下去】\n将勇气的祈愿附在音色之中【将其克服】\n用那约定相连的指尖弹起\n不知不觉【奏响吧】就在你身旁奏响的\n即使是还无法实现\n【面对于你的命运啊】\n我自己啊 继续前行吧…！ | P11: 决心交响曲，roselia
A12: PASSIONATE ANTHEM | B12: PASSIONATE ANTHEM | C12: Ave Mujica 0th LIVE 「Primo die in scaena」现场表演 | D12: 2023 | E12: 45081 | F12: images/logo/pa.webp | G12: Cover | H12: 織田あすか(Elements Garden) | I12: 藤永龍太郎(Elements Garden) | J12: 藤永龍太郎(Elements Garden) | K12: Ave Mujica 0th LIVE 「Primo die in scaena」 | M12: (We went all out to win)\nPassionate Gaze\n(We went all out to win)\nPassionate Voice\n(We went all out to win)\nPassionate Soul\n(We went all out to win)\n眼差しは 唯ひたすらに愚直さを込めて\n魂と本能をくすぐっていった\n新たな挑戦が 本物へと近づく…\nどんなステージだって 微笑みをあげるわ\n(Breaking out)逆鱗に触れた先に落ちた\n(Breaking out)産声が激しくぶつかり合う宴\n競い咲くように 命の Anthem 嗚らして\n磨き上げてゆく それぞれのダイヤを胸に抱き\n自らの音を 信じているからと 高らかに\n妥協はしない 譲らない 決して揺るがないものは\n誇りある この想い\n(We went all out to win)\nPassionate Song\n(We went all out to win)\nRush!\n声と声 重ね合って\n目覚めてゆく細胞はAmazing\nChallenge\nその姿は 正に異端児\nRush!\nFreed\n盤上に開く夢へのGate\nかかって来なさい、勝てると思うのならば\n(Living on)互いのセオリー響き合わせて\n(Living on)目覚ましく現れた熱情が光る\n常に燃え尽きることなく 心を動かして\n言の葉の世界が煌びやかに ひらり舞い踊る\n授かったものを 輝かしく育ててゆくまで\n崩れはしない 倒れない 決して壊れないものは\n誇りある この絆\n私たちの最果ては何処なのか\n己の中を追い求め走り出す\nこの正解を手に入れるまでは\nAre you ready? …容赦しない\n競い咲くように 命の Anthem 嗚らして\n磨き上げてゆく それぞれのダイヤを胸に抱き\n自らの音を 信じているからと 高らかに\n妥協はしない 譲らない 決して揺るがないものは\n誇りある 仲間たち\n(We went all out to win)\nPassionate Gaze\n(We went all out to win)\nPassionate Voice\n(We went all out to win)\nPassionate Soul\n(We went all out to win) | N12: 我们为了赢而拼尽全力\n激情的凝视\n我们为了赢而拼尽全力\n激情的声音\n我们为了赢而拼尽全力\n激情的灵魂\n我们为了赢而拼尽全力\n凝视的目光直直刺入愚昧的正直\n灵魂和本能一直蓄势待发\n新的挑战离真实之物近在咫尺\n无论走上怎样的舞台 我们都会献以微笑\n（爆发吧）在触碰到逆鳞之前他们就已四散而逃\n（爆发吧）这是初生之啼哭激烈碰撞的盛宴\n这竞相绽放的生命之颂歌被奏响了\n把每个人的宝石一点点地擦亮 在胸前抱紧\n因为尽力相信 自己的声音才越发高昂\n不妥协 不退让 决不动摇的东西\n就是这值得骄傲的意志\n我们为了赢而拼尽全力\n激情的乐曲\n我们为了赢而拼尽全力\n冲刺吧！\n每个人的声音重合放大\n正在觉醒的细胞可谓惊奇\n超越突破极限的挑战\n这般姿态简直就是异端之子\n冲刺吧！\n这成长的双翼不受束缚\n通往梦想的门自由敞开\n全都放马过来吧 如果觉得能赢过我们的话\n（以此为生）让彼此的信条交织奏鸣\n（以此为生）这闪光的热情震撼登场\n这永不熄灭的心跳动起来了\n这由言语组成的世界光辉灿烂地起舞了\n在所有领悟到的东西全部可以尽情闪耀之前\n不会崩塌 不会被击倒 绝对无法被破坏的\n就是这值得为之自豪的羁绊\n我们的终点到底在何处\n为追求自己的内在而开始奔跑\n在把这正解得到手之前\n你准备好了吗？不会有一点宽容\n这竞相绽放的生命之颂歌被奏响了\n把每个人的宝石一点点地擦亮 在胸前抱紧\n因为尽力相信 自己的声音才越发高昂\n不妥协 不退让 决不动摇的东西\n就是值得为之自豪的朋友们\n我们为了赢而拼尽全力\n激情的凝视\n我们为了赢而拼尽全力\n激情的声音\n我们为了赢而拼尽全力\n激情的灵魂\n我们为了赢而拼尽全力 | P12: roselia
A13: Utopia | B13: 素晴らしき世界 でも どこにもない場所 | C13: Digital Single | D13: 2023 | E13: 45290 | F13: images/utopia.webp | G13: Original | H13: Diggy-MO' | I13: 長谷川大介(SUPA LOVE) | J13: 長谷川大介(SUPA LOVE) | K13: Ave Mujica 1st LIVE「Perdere Omnia」 | L13: https://www.bilibili.com/video/BV1Xg4y1k7GH | M13: 失えばいい たったひとつのひかり目指すため\n壊せ 壊せと いつも叫んでる 牙を剥く夜\n嘆くな 憂うな きっとこころは知っているはずさ\n \n輝ける時代（とき）の波よ いまはもう幻と移ろう風よ\n破壊が ほら もたらすわ すべてを\n \n[now all the walls will come down] 新たなる火を\n \n \n \n巡る 時計の数字 消してゆく夜\n理想郷 信念が描き出す‘素晴らしき世界’ でも ‘どこにもない’\n‘どこにもない場所’へと\n \n静かなるその熱情よ 届くのだと想い馳せる夢追い人よ\n破壊が また もたらすわ 真実を\n \n \n \n[now all the walls come down] 何が見える 何を見る\n[let's get it off the ground] そう いま架け橋になる\nさあ 怯むことなく 尊い思想に\n何をも恐れず 命を誘うように\n \n輝ける時代（とき）の波よ いまはもう幻と移ろう風よ\n破壊が ほら もたらすわ すべてを\n \n[now all the walls will come down] 新たなる火を | N13: 失去也无妨 只为追寻那唯一的光芒\n破坏吧 破坏吧 总这样嘶吼着 那露出獠牙的夜晚\n莫悲叹 莫忧愁 心一定早已知晓\n \n辉煌时代的浪潮啊 如今已是幻影与流转之风啊\n破坏带来的 看吧 是一切\n \n[now all the walls will come down] 带来新生之火\n \n \n \n将轮转的时钟数字 渐渐抹去的夜啊\n乌托邦 信念描绘出的‘美好世界’，却‘哪里都不存在’\n向着‘哪里都不存在的地方’\n \n那沉静的热情啊 怀揣着终将能够抵达念想的逐梦者啊\n破坏带来的 再度 是真实\n \n \n \n[now all the walls come down] 能看见什么 选择去看什么\n[let's get it off the ground] 是的 此刻化为桥梁\n来吧 毫不退缩地 向着那崇高的思想\n无所畏惧 如同召唤生命\n \n辉煌时代的浪潮啊 如今已是幻影与流转之风啊\n破坏带来的 看吧 是一切\n \n[now all the walls will come down] 带来新生之火 | O13: 素晴らしき世界 でも どこにもない場所,Ave Música | P13: 素晴，乌托邦
A14: Angles | B14: Angles | C14: Digital Single | D14: 2024 | E14: 45298 | F14: images/angles.webp | G14: Original | H14: Diggy-MO' | I14: 長谷川大介(SUPA LOVE) | J14: 長谷川大介(SUPA LOVE) | K14: Ave Mujica 1st LIVE「Perdere Omnia」 | L14: https://www.bilibili.com/video/BV1Ai4y167MU | M14: 訪れたの いま 連れ出すため\n明日に落とす 静寂と月明かり\n見つめている 感じている 歪んだ刻（とき）の中で\nあらゆる日々は そう この‘刻（とき）’のため\n \n‘すべての段階’ そのリストを ひとつ またひとつ 燃やすの\n \ndon't be serious 身を任せて 夜が創られてゆく\ndon't be serious もう一度 あの月が満ちたら\ncurious, so curious 怖くなるほど綺麗でしょ\n‘死’それは私たちを結びつけるわ\n \n \n \n生まれるのね 祝福とともに\n未来照らす産声を轟かせ\n伝えるべきものをと いざ 創られし新たなる物語（ストーリー）\nあらゆる日々は そう この‘瞬間（とき）’のため\n \n背景がまた変わる めくるページ さあ 目眩く激情\n \ndon't be serious 思うままに空を彩どるのは\ndon't be serious もう二度と振り返らぬ証\ncurious, so curious 繰り返すのね 愚かでしょ\n‘生’それが私たちを分かつものなの\n \n \n \nYou and I ‘God's Creation’\n \ndon't be serious 身を任せて 夜が創られてゆく\ndon't be serious もう一度 あの月が満ちたら\ncurious, so curious 怖くなるほど綺麗でしょ\n‘死’それは私たちを結びつけるわ | N14: 到来了 此刻 为了将我们带走\n将寂静与月光 洒落于明日\n凝视着 感受着 在扭曲的时光之中\n所有的日子 是的 都是为了此刻\n \n‘所有的阶段’ 将那清单 一项又一项付之一炬\n \ndon't be serious 交托身体 夜晚正被逐渐创造\ndon't be serious 再一次 当那轮月亮再次盈满\ncurious, so curious 美丽到使人畏惧吧？\n‘死’ 它会将我们连结在一起\n \n \n \n要诞生了呢 与祝福一同\n让照亮未来的初啼响彻\n为传达那应传达之物 来吧 就此创生的崭新故事\n所有的日子 是的 都是为了这 '瞬间'\n \n背景再度变幻 翻动书页 来吧 令人目眩的激情\n \ndon't be serious 随心所欲地为天空着色\ndon't be serious 这便是再也不回头的证明\ncurious, so curious 还在重复着呢 很愚蠢对吧\n‘生’ 那是会将我们分离之物\n \n \n \nYou and I 'God's Creation'\n \ndon't be serious 交托身体 夜晚正被逐渐创造\ndon't be serious 再一次 当那轮月亮再次盈满\ncurious, so curious 美丽到使人畏惧吧？\n‘死’ 它会将我们连结在一起 | O14: 素晴らしき世界 でも どこにもない場所 | P14: 角
A15: Symbol I : Fire | B15: Symbol I : 🜂 | C15: Digital Single | D15: 2024 | E15: 45389 | F15: images/fire.webp | G15: Original | H15: Diggy-MO' | I15: 長谷川大介(SUPA LOVE) | J15: 長谷川大介(SUPA LOVE) | K15: Ave Mujica 2nd LIVE「Quaerere Lumina」神奈川公演 | L15: https://www.bilibili.com/video/BV1GJ4m1E7F4 | M15: 絵画が燃える 騎士（ナイト）が消える\n何がほざく 黙らぬ夢に\n私はいる あなたの視界の陰に革命を描くの\n \nthis is the way 背筋襲う光 浮き上がる火の竜と\ninto the realm やがて出逢うわ 西の城壁で\n焼けてくロザリオ 逆巻く炎 ilala,ilala,\nこの記憶 孤高の記憶 神の唯一の過ち\n人は皆 完全なものを語れないわ\nいつの時代（とき）も残酷さが美を創り 世界は悦んで蠢き出す\n \n探しているわ\n \n \n \n闇は報い 何が救い\n歴史の海に反射する星よ\n軋む胸に刻めよ 弔えよ霊を 名もなき英雄を\n \nthis is the way 咽せ返る薔薇の楽園に臨めば\ninto the realm 決まるこの心 いざいま ゆくだろう\n \n煌めくロザリオ 導く者 ilala,ilala,\nこの記憶 孤高の記憶 誰も奪えはしないわ\n刻は来た 世界が私だけを忘れてく\n近づいたの 行き過ぎたの でもいいわ すべてを取り戻せるのなら\n \n迎えに来たのね さあ 私を連れてゆけ\n赤く咲き誇る この哀しい空に\nねぇ\n \n焼けてくロザリオ 逆巻く炎 ilala,ilala,\nこの記憶 孤高の記憶 神の唯一の過ち\n人は皆 完全なものを語れないわ\nいつの時代（とき）も残酷さが美を創り 世界は悦んで蠢き出す\n \n探しているわ | N15: 画作燃烧 骑士消失\n谁在胡言乱语 对着不愿沉默的梦\n我在此处 于你视野的阴影中描绘革命\n \nthis is the way 令脊背战栗的光芒 与浮现而出的火龙\ninto the realm 终将相遇 在西面城墙下\n渐燃的玫瑰念珠 翻卷的火焰 ilala, ilala,\n这份记忆 孤高的记忆 是神唯一的过错\n人皆无法言说完美之物\n任何时代都是残酷创造着美 世界欢欣地开始蠢动\n \n我正在寻找啊\n \n \n \n暗为报偿 何为救赎\n倒映在历史之海中的星星啊\n铭刻于作痛的胸中 悼唁亡灵吧 悼唁那无名的英雄\n \nthis is the way 当来到那令人窒息的玫瑰乐园\ninto the realm 此心已决 现在 就出发吧\n \n闪耀的玫瑰念珠 引导者 ilala, ilala,\n这份记忆 孤高的记忆 谁都无法夺走\n时刻已至 世界正唯独将我遗忘\n是更近一步 还是已然越界 都无妨 只要能够夺回一切\n \n你是来接我的吧 来 带我走\n赤红盛放 在这悲伤的天空之下\n啊\n \n渐燃的玫瑰念珠 翻卷的火焰 ilala, ilala,\n这份记忆 孤高的记忆 是神唯一的过错\n人皆无法言说完美之物\n任何时代都是残酷创造着美 世界欢欣地开始蠢动\n \n我正在寻找啊 | O15: ELEMENTS,Ave Música | P15: 火，元素一，1
A16: Symbol II : Air | B16: Symbol II : 🜁 | C16: Digital Single | D16: 2024 | E16: 45430 | F16: images/air.webp | G16: Original | H16: Diggy-MO' | I16: 高橋涼(SUPA LOVE) | J16: 高橋涼(SUPA LOVE) | K16: Ave Mujica 2nd LIVE「Quaerere Lumina」神奈川公演 | L16: https://www.bilibili.com/video/BV1A7421o7Di | M16: この風が そう‘嵐’ を呼ぶわ\n私を奏でる誰かの言葉\n唄いながら闇に踊れ 笑いながら やあ 泣き濡れて ただ\nha-ha, わからないわ なにもないから\n \nでも 世界が望むのならば そうね\nハルピュイア ケルベロス ああ 何物にでもなれるわ\n \nまだまだよ まだね まだまださ まだ\n何度でも kiss をする色のない私\nまだまだよ まだね まだまださ\nでも なぜかしらね なにをしても虚しいの\n \n \n \n頼れないもう 時の魔法に\n奪われた秩序 ああ 北の空\n降り注ぐ大雨の中 朽ち果てるその魂が ほら\nha-ha, 時代を司る大義名分とやら\n \nでも 神が見ているのならば 唄い 踊らねば\n再び ‘嵐’ を呼ぶ 仰せのままに\n \nまだまだよ まだね まだまださ まだ\n彼らを翻弄するわ 求めない私\nまだまだよ まだね まだまださ\nほらでも あなたも そう きっと同じなのね\n \n‘この大地にあるものはすべて消え去る’ と\nからがら あなたならあらためるかしら\n \nまだまだよ まだね まだまださ まだ\n何度でも kiss をする色のない私\nまだまだよ まだね まだまださ\nでも なぜかしらね なにをしても虚しいの | N16: 这风 是啊 呼唤着 ‘暴风雨’\n某人的话语奏响了我\n一边歌唱一边在黑暗中舞蹈 一边笑着 呀 泪流满面 只是\nha-ha, 我不知道啊 因为一无所有\n \n但是 如果是世界所期望的话\n哈耳庇厄 刻耳柏洛斯 啊啊 可以成为任何东西\n \n还不够啊 还不够 还远远不够 还不\n无色的我一次又一次地亲吻\n还不够啊 还不够 还远远不够\n但是 为什么呢 无论做什么都觉得空虚\n \n \n \n已经无法依赖 时间的魔法\n被夺走的秩序 啊啊 北方的天空\n在倾盆大雨中 那彻底腐朽的灵魂 你瞧\nha-ha, 所谓支配这个时代的大义名分\n \n但是 如果神在注视着 我便不得不唱歌 起舞\n再次召唤 ‘暴风雨’ 悉听尊命\n \n还不够啊 还不够 还远远不够 还不\n我会玩弄他们 别无所求的我\n还不够啊 还不够 还远远不够\n但你瞧 你也是 是的 你一定也是一样的呢\n \n‘这大地上的一切都将消逝’\n狼狈不堪 如果是你 会就此改变吗\n \n还不够啊 还不够 还远远不够 还不\n无色的我一次又一次地亲吻\n还不够啊 还不够 还远远不够\n但是 为什么呢 无论做什么都觉得空虚 | O16: ELEMENTS,Ave Música | P16: 气，风，元素二，2，马达
A17: Symbol III : Water | B17: Symbol III : 🜄 | C17: Digital Single | D17: 2024 | E17: 45458 | F17: images/water.webp | G17: Original | H17: Diggy-MO' | I17: トミタカズキ(SUPA LOVE) • Diggy-MO' | J17: トミタカズキ(SUPA LOVE) | K17: Ave Mujica 2nd LIVE「Quaerere Lumina」爱知公演 | L17: https://www.bilibili.com/video/BV17w4m1Y7kf/ | M17: 月を詠む 海のリズム\n私は ‘最初に降り立った者’\n流れ出す このプログラム\n引き合う魂 魂の歌が\n\n叫ぶの 欲望を 命の緊張を高めてゆくわ\n\n寄せる 寄せる 寄せる波 私の性の中で\n馳せる 馳せる 馳せる夢 微かな音を抱きしめて\n揺れる 揺れる 揺れる愛 あなた対極にいて その炎と重なって\nいま ‘大宇宙(おおぞら)’になる\n\n\n\n可哀想に おいでなさい\nついには影を手放したのね\n古い本は焼き払われ\n時代が通り過ぎてゆく\n\nいまでも 幸せなその’死’の訪れをただ祈りながら\n\n寄せる 寄せる 寄せる波 すべてを 嗚呼 受け入れて\n馳せる 馳せる 馳せる夢 何もかもを失って\n揺れる 揺れる 揺れる愛 遠く近く あなたの炎が舞い上がる\n世界は白くなる\n\n\n\n導くように\n小さな磁気を帯びて煌めいている場所がある\nそう 私はかつて最初に降り立った者\nこの白き世界に\n\n寄せる 寄せる 寄せる波 ‘生’の中で\n馳せる 馳せる 馳せる夢 微かな音を抱きしめて\n揺れる 揺れる 揺れる愛 ああ その命(ほのお)と重なって\nいま ‘大空’になる | N17: 吟咏月色 海之节奏\n我是“最初降临之人”\n既定的程式运作流转\n彼此吸引的灵魂 灵魂之歌\n\n呐喊的欲望 绷紧生命的琴弦\n\n翻涌 翻涌 波浪层层涌来 在我的天性中激荡\n疾驰 疾驰 梦想奔向远方 怀抱微弱的余音\n摇曳 摇曳 爱情动摇不定 与身处对极的你 同那火焰重叠在一起\n此刻 化作广阔天空\n\n\n\n真是可怜 过来吧\n终于舍弃了影子呢\n旧书被焚毁\n一个时代渐渐远去\n\n直到如今 仍只祈祷着幸福的死亡降临\n\n翻涌 翻涌 波浪层层涌来 啊啊 将所有尽数接纳\n疾驰 疾驰 梦想奔向远方 纵然失去一切\n摇曳 摇曳 爱情动摇不定 似近似远 你的火焰飞扬而起\n世界变得一片纯白\n\n\n\n仿佛命运指引一般\n有处地方带微弱的磁场 闪烁光芒\n没错 我是最初降临于此之人\n在这纯白的世界\n\n翻涌 翻涌 波浪层层涌来 在生命之中\n疾驰 疾驰 梦想奔向远方 怀抱微弱的回响\n摇曳 摇曳 爱情动摇不定 啊啊 与生命之火交融\n此刻 化作无垠宇宙 | O17: ELEMENTS | P17: 元素水，窝塔，元素三，3
A18: Symbol IV : Earth | B18: Symbol IV : 🜃 | C18: Digital Single | D18: 2024 | E18: 45481 | F18: images/earth.webp | G18: Original | H18: Diggy-MO' | I18: 長谷川大介(SUPA LOVE) • Diggy-MO' | J18: 長谷川大介(SUPA LOVE) | K18: Ave Mujica 3rd LIVE「Veritas」 | L18: https://www.bilibili.com/video/BV1Cz421e79N | M18: 紡いでゆくの\nかつて この地が幾多の文化を慈しんだように\n捧げているの\n紅い花が咲くとき 入り口は開かれるわ\n \ncome into me 次の人生を ああ 嗚呼 形どるの\nそうよ いつか飛び立つときを知るでしょう\n \n差し出されたサフラン色の翼\nいまはそこに 光を纏って\nyou are.. you are.. you are my reason to be\nyou’re my only 自由になって\n \n \n \n還ってゆくの\n下腹部に耳を当て 星の鼓動を数えながら\n \ncome into me and again さあ 礎をもてば 描けるわ\nそうよ そのときのため\n \n追憶に蘇る アイリスの恵み 雨\n広がる緑 赤土の丘に青い弓が張り 大地に美しいスカーフが架かる\n \n \n \n差し出されたサフラン色の翼\nいまはそこに 光を纏って\nyou are.. you are.. you are my reason to be\nyou're my only.. you’re my only.. you are my reason\n \nyou are my reason | N18: 就此编织下去\n正如这片大地曾珍爱过无数文化那般\n奉献\n当红花绽放之时 入口将会开启\n \ncome into me 将下一段人生 啊啊 塑造成型\n是啊 总有一天会知晓展翅高飞之时吧\n \n那被给予的藏红花色翅膀\n如今在那里 披覆着光芒\nyou are.. you are... you are my reason to be\nyou're my only 获得自由吧\n \n \n \n归去\n附耳于小腹 细数星辰的心跳\n \ncome into me and again 来吧 若拥有基石 便能绘出\n是啊 正是为了那一刻\n \n在追忆中复苏的 伊里斯之恩泽 雨\n绿意铺展 蓝弓张于红土丘陵 美丽的长带横跨大地\n \n \n \n那被给予的藏红花色翅膀\n如今在那里 披覆着光芒\nyou are.. you are... you are my reason to be\nyou're my only.. you’re my only.. you are my reason\n \nyou are my reason | O18: ELEMENTS | P18: 地，土，元素四，4
A19: Ether | B19: Ether | C19: Digital Single | D19: 2024 | E19: 45534 | F19: images/ether.webp | G19: Original | H19: Diggy-MO' | I19: 長谷川大介(SUPA LOVE) • Diggy-MO' | J19: 長谷川大介(SUPA LOVE) | K19: Ave Mujica 3rd LIVE「Veritas」 | L19: https://www.bilibili.com/video/BV1D12BYUEXn | M19: 一葉の銀河系\n夢を描く\n幻をああ 体験しているのね\n星図にはないわ いま 刻（とき）のしじまを破って命が流転する\n宇宙（そら）のオーケストラ 人の願望とは果てしなく\n \n月より下に時代を創って 何者かになるのね\n \nでもね 知ってほしい 本当の光を\n静寂の中でだけ輝くその光\nあなたに 知ってほしい 真実（ほんとう）の輝きを\n深い闇の中でそれを知り 決して 忘れてはいけない\n \n \n \n複雑性の一面を人は運命と呼ぶ\n自分らしさに拘らないで\n計り知れないところで巡ってゆく\n \n月より下に それでも掲げ 闘うのね\n \nでもね 知ってほしい 本当の光を\n静寂の中でだけ輝くその光\nあなたに 知ってほしい 真実（ほんとう）の輝きを\n深い闇の中でそれを知り 決して 忘れてはいけない\n \n \n \n自由になる\n廻る やがて調和が訪れる\nそのとき 自由という概念も無くなるわ\nまた 宇宙（そら）へ 還ってゆく | N19: 一叶银河系\n描绘着梦\n啊啊 正在体验幻象呢\n星图之上不存在 此刻 打破时光的寂静 生命流转\n宇宙的管弦乐 所谓人的愿望 无穷无尽\n \n在月亮之下开创时代 会成为某种存在吧\n \n但是啊 希望你知晓 真正的光芒\n那道只在寂静之中闪耀的光芒\n希望你知晓 真实的光辉\n在深邃的黑暗中知晓它 绝对 不能忘记\n \n \n \n复杂性的一面 人们称之为命运\n不要拘泥于自我本色\n于不可测知之处循环流转\n \n在月亮之下 即便如此仍高举着 战斗着呢\n \n但是啊 希望你知晓 真正的光芒\n那道只在寂静之中闪耀的光芒\n希望你知晓 真实的光辉\n在深邃的黑暗中知晓它 绝对 不能忘记\n \n \n \n获得自由\n周而复始 和谐终将降临\n届时 自由这一概念也将不复存在\n再一次 归于宇宙 | O19: ELEMENTS,Ave Música | P19: 以太，元素五，5
A20: KiLLKiSS | B20: KiLLKiSS | C20: Ave Mujica 4th LIVE「Adventus」现场表演 | D20: 2024 | E20: 45641 | F20: images/kk通常.webp | G20: Original | H20: Diggy-MO' | I20: 長谷川大介(SUPA LOVE) • Diggy-MO' | J20: 長谷川大介(SUPA LOVE) | K20: Ave Mujica 4th LIVE「Adventus」 | L20: https://www.bilibili.com/video/BV1g4E4zsEQr | M20: 弄られて垂れ流す 音のない音\n遍く 名前を捨てたのね あなたのモザイクが泣いてる\ncan not, can not, not, not, not deny 紛れもなく真実\nさあ 預けて 回帰するように\n \nエネルギーはサイクル そう いまは無重力\n象徴的なパレード この月夜に仰げよ仰げ\n‘completeness’\n嗚呼 命の灯を掲げ\n \nKiLLKiSS judy.., KiLLKiSS jude.., KiLLKiSS juda..,\n欺いて\nKiLLKiSS judy.., KiLLKiSS jude.., KiLLKiSS juda..,\n抱きしめて\nねぇ 無防備だね 美しい戯れに 人は壊れてゆく\n可笑しいわね\n \n \n \n'cuz we're all alone\nalone, 噛み締めても まだ痛むなら\n \n手を挙げ 希え\noh, when you bleed, 惑星に そう その影を伸ばせ\nねぇ 私の世界（ほし）が知りたがっているわ さあ\nyou bleed, yes, bleed その血で 天（そら）の五線譜を書き換えれば\ncode ‘KiLLKiSS’ uh..,\n \nKiLLKiSS judy.., KiLLKiSS jude.., KiLLKiSS juda..,\n欺いて\nKiLLKiSS judy.., KiLLKiSS jude.., KiLLKiSS juda..,\n抱きしめて\nねぇ あからさまね 醜い終局に すべてが変わってゆく\n儚いのね\n \nそう このまま 壊れて | N20: 被玩弄着倾泻出 无声之音\n舍弃了一切名字呢 你的马赛克正在哭泣\ncan not, can not, not, not, not deny 毫无疑问的真相\n来吧 托付于我 如同回归一般\n \n能量循环往复 是的 此刻已然失重\n象征性的游行 于此月夜仰望吧 仰望\n‘completeness’\n啊 高举生命之灯\n \nKiLLKiSS judy.., KiLLKiSS jude.., KiLLKiSS juda..,\n瞒天过海\nKiLLKiSS judy.., KiLLKiSS jude.., KiLLKiSS juda..,\n紧抱入怀\n真是毫无防备啊 人在这甜美嬉戏中逐渐崩坏\n真是可笑呢\n \n \n \n'cuz we're all alone\nalone, 倘若咬紧牙关依旧疼痛\n \n高举双手 祈愿吧\noh, when you bleed, 向着行星 是的 延伸阴影\n呐 我的世界正渴望知晓 来吧\nyou bleed, yes, bleed 那血液 若能改写天空的五线谱\ncode ‘KiLLKiSS’ uh..,\n \nKiLLKiSS judy.., KiLLKiSS jude.., KiLLKiSS juda..,\n瞒天过海\nKiLLKiSS judy.., KiLLKiSS jude.., KiLLKiSS juda..,\n紧抱入怀\n多么昭然若揭啊 一切逐渐走向丑陋终局\n真是虚幻啊\n \n是的 就这样 毁坏吧 | O20: KiLLKiSS,Completeness,Ave Música | P20: kk，杀吻，op
A21: Georgette Me, Georgette You | B21: Georgette Me, Georgette You | C21: 『BanG Dream! Ave Mujica』#1～#3 电影院先行上映 | D21: 2024 | E21: 45653 | F21: images/GMGY.webp | G21: Original | H21: Diggy-MO' | I21: 松坂康司（SUPA LOVE） | J21: 松坂康司（SUPA LOVE） | K21: リスアニ!LIVE 2025 SATURDAY STAGE | L21: https://www.bilibili.com/bangumi/play/ep1365126 | M21: 白銀の糸を伝い 想い 手繰り寄せてた\nその果てで妊る月 抱きしめたなら\n \n待っているの 太陽から夜が堕ちてくるのを\nねぇ その果てで満たしてよ 届く気がするの\n \nもつれたまま 踊る Georgette Me, Georgette You まわる\n痛むほどに ほら 煌めくドレスを纏いながら\n \neverlastin’ ever.. darlin’ ever, ever.. 締め付けて again\neverlastin’ ever.. 離れぬように ever, ever, ever..\n\n\n\n縛るものはなに？ それは 誰かの遠い祈り\nああ 最初から知っていたわ 許されないこと\n \n愛せぬまま 踊る Georgette Me, Georgette You is that true?\nあなたが触れたわ この傷口に\n\n\n\nもつれたまま 踊る Georgette Me, Georgette You まわる\nこのまま このままでいさせて\n\n\n\n愛せぬまま 踊る Georgette Me, Georgette You is that true?\n痛みは光ね 煌めくドレスを纏いながら\n \neverlastin’ ever.. darlin’ ever, ever.. 締め付けて again\neverlastin’ ever.. 離れぬように ever, ever, ever.. | N21: 沿着白银的丝线 将思念牵至身边\n在那尽头所孕育的月 若能将它拥入怀中\n \n等待着 夜晚从太阳坠落\n啊 在那尽头将我满足 思绪仿佛能够传达\n \n缠绵不清 翩翩起舞 Georgette Me, Georgette You 旋转不停\n越是痛苦不已 看啊 身缠礼服愈加闪耀\n \n直到永远…亲爱的 永远永远…再次将你我紧缚\n直到永远…为了永不分离 永远 永远 永远…\n\n\n\n束缚我们的是什么？是某人遥远的祈祷\n啊啊 最初我便知晓 这是不被允许之事\n \n无法相爱 翩翩起舞 Georgette Me, Georgette You 这是否真实？\n是你触碰到了啊 这处伤口\n\n\n\n缠绵不清 翩翩起舞 Georgette Me, Georgette You 旋转不停\n就这样 就让我们一直这样下去\n\n\n\n无法相爱 翩翩起舞 Georgette Me, Georgette You 这便是真实？\n痛苦是光明呢 看啊 身缠礼服闪耀至此\n \n直到永远…亲爱的 永远 永远…再次将你我紧缚\n直到永远…为了永不分离 永远 永远 永远… | O21: KiLLKiSS,Completeness,Ave Música | P21: GMGY,ed，缠你缠我
A22: DIVINE | B22: DIVINE | C22: 游戏『PROGRESS ORDERS』OP Moive公开 | D22: 2025 | E22: 45674 | F22: images/DIVINE.webp | G22: Original | H22: Diggy-MO' | I22: 高橋涼 (SUPA LOVE) • Diggy-MO' | J22: 高橋涼 (SUPA LOVE) | K22: Ave Mujica 5th LIVE「Nova Historia」DAY1 | L22: https://www.bilibili.com/video/BV1EvcdenE9h | M22: さやめく光は 夢見る悪魔か\n遠き予言者なのか\n仕掛けられたアレゴリーが動き出したこの宙（そら）\nエレメンタル覗くのは\n \n天球の Blue World そこに生きる者 \n冒険者よ 共にゆこう さあ いざ\n \nその眼が捕える その眼が創る その眼が愛する 時代（とき）よ\n謎めくは運命（さだめ） いま 変えてゆくのさ\n \nDIVINE DIVINE 闇夜を貫く眩い Vision（未来）へ\n輝ける新たな真実を描いて\n \n \n \nささやかなことから始まる破滅が\n人を悲哀へと\n狂おしいほど疲れ切った魂を蝕むあからさまな現実よ\n \n境目の Cruel World そこに生きる者\nなにもかもが正しくなくてもいい\n \nその瞳に惹かれる その瞳に歌う その瞳に見つめる 君よ\n同じ悲しみに いま 寄り添いたい\n \nDIVINE DIVINE震える想い 張り裂けそうで\nああ 忘れないで 本当の心だけ抱きしめて\n \n \n \nDIVINE, so DIVINE\n \n \n \n歴史の狭間 揺れる世界で 寂しさが人を繋ぐのかもしれない\nぬくもりの中で また 汚れた\n生きてゆくため そう そのために 理由が 答えが 欲しいのか 何故\n嗚呼 蒼き熱情よ\nならば ならば 教えてくれ\n \n \n \nその眼が捕える その眼が創る その眼が愛する 時代（とき）よ\n謎めくは運命（さだめ） いま 変えてゆくのさ\n \nDIVINE DIVINE闇夜を貫く眩い Vision（未来）へ\n輝ける新たな真実を描いて | N22: 沙沙低语的光芒 是做梦的恶魔吗\n还是遥远的预言者呢\n这片天空中 被布置好的寓言开始运转\n窥视着元素的是\n \n天球之上的 Blue World 生活于其中的人们\n冒险者啊 一起前行吧 来吧 出发\n \n那双眼所捕捉 那双眼所创造 那双眼所爱的 时代啊\n神秘莫测的正是命运 此刻 逐渐改变\n \nDIVINE DIVINE 向着那贯穿暗夜的耀眼 Vision（未来）\n描绘那闪耀的崭新真实\n \n \n \n从微不足道之事开始的毁灭\n将人引向悲哀\n侵蚀着疲惫得近乎疯狂的灵魂的赤裸裸的现实啊\n \n边界上的 Cruel World 生活于其中的人们\n一切即便都不正确也无妨\n \n被那双眼吸引 向那双眼歌唱 凝望那双眼的 你啊\n想要在此刻 依偎于同样的悲伤\n \nDIVINE DIVINE 颤抖的思念几近迸裂\n啊 请不要忘记 只拥抱那颗真正的心\n \n \n \nDIVINE, so DIVINE\n \n \n \n在历史的夹缝中 摇荡的世界里 也许是寂寞将人们相连\n在温暖之中 又染上了污秽\n为了活下去 是的 正因如此 才想要理由 想要答案吗 为何\n啊啊 苍蓝的热情啊\n那么 那么 请告诉我\n \n \n \n那双眼所捕捉 那双眼所创造 那双眼所爱的 时代啊\n命运正是神秘莫测 此刻 逐渐改变\n \nDIVINE DIVINE 向着那贯穿暗夜的耀眼 Vision（未来）\n描绘那闪耀的崭新真实 | O22: Ave Música | P22: 迪歪，神圣
A23: Imprisoned XII | B23: Imprisoned XII | C23: 『BanG Dream! Ave Mujica』#10 插入曲 | D23: 2025 | E23: 45722 | F23: images/囚12.webp | G23: Original | H23: Diggy-MO' | I23: 松坂康司（SUPA LOVE） | J23: 松坂康司（SUPA LOVE） | K23: MyGO!!!!!×Ave Mujica 合同ライブ「わかれ道の、その先へ」DAY1 : Petrichor | L23: https://www.bilibili.com/video/BV1Ep91YPEQo | M23: ねじれた空を描いて思うの 羽根のない君 堕ちればいい\n触れてしまった神聖なもの 今夜 私の神話になって\n \nほら 逃げられないわ 弱っていく君 閉じ込めて\n \nyou know i want... i want... i want... i want you so, i want...\nいなければよかったのに なぜ\nyou know... you know... you know... you know i want you to know how much i need you so,\nいま 狂おしいほど\n \n \n \nわかってるの でも いまは密やかに 奇妙な時間をただ君と\n冷たいこの手で 愛すべきもの 葬る私を受け入れて\n \n危きこころの壁に 忍ぶは理不尽な夢\n \ni say, you're mine... you're mine... ほら すぐそこにいるのに\n \n叶わない それでも i want... i want... i want you so, i want...\n想い出なんていらない だから\nyou know... you know... you know... so, you know i want you to know how much i need you so\nいま 狂おしいほど | N23: 描绘扭曲天空 我不禁遐想 没有羽翼的你 就这样坠落吧\n触碰到了神圣之物 今夜 成为我的神话吧\n \n看吧 你已无路可逃 将逐渐虚弱的你 囚禁起来\n \nyou know i want... i want... i want... i want you so, i want...\n若不存在该多好 为何\nyou know... you know... you know... you know i want you to know how much i need you so,\n此刻我如痴如狂\n \n \n \n我知道的 可是此刻只想悄然与你共度这奇妙时光\n以冰冷的双手 埋葬本该珍爱之物 请接纳这样的我吧\n \n摇摇欲坠的心墙之中 潜藏着荒诞的梦\n \ni say, you're mine... you're mine... 看吧 明明近在咫尺\n \n无法实现 纵使如此 i want... i want... i want you so, i want...\n我不需要什么回忆 所以……\nyou know... you know... you know... so, you know i want you to know how much i need you so\n此刻我如痴如狂 | O23: Completeness,Ave Música | P23: 囚禁，监禁，囚12
A24: Crucifix X | B24: Crucifix X | C24: 『BanG Dream! Ave Mujica』#10 插入曲 | D24: 2025 | E24: 45722 | F24: images/十字架.webp | G24: Original | H24: Diggy-MO' | I24: o-saka(SUPA LOVE) • Diggy-MO' | J24: o-saka(SUPA LOVE) | K24: MyGO!!!!!×Ave Mujica 合同ライブ「わかれ道の、その先へ」DAY1 : Petrichor | L24: https://www.bilibili.com/video/BV1iEQ6YCECx | M24: あぁ 私を辱めたあなたのメロディは いまだ猛り狂うのか\n \n戦慄のカテドラル 抗う心臓\n焼けてゆく後ろ髪のないフォルトゥーナ\n \nstill alive 命の歯車が so, still alive 回り出す\n振り切る己をゆく\nstill alive? ロゴスの誘いは so, still alive? まだ見えない\n汚れてく異教徒たちの涙\n \n \n \n[face] so, we got to face this [face] we got to face\n[face] 繰り返す 疎外 虚勢 絶望 鎮まらぬ魂 人は何故\n \nstill alive 誰かの歯車が so, still alive 狂い出す\n忌まわしい鐘楼が鳴る\nstill alive? ‘来るべき世界’は so, still alive? 求めている\n処刑台の終わりなき犠牲者\n \n \n \nnever die 歴史の血の河を i never die 掻い潜り\n彷徨える 我が十字架\n \n \n \nstill alive 命の歯車が so, still alive 回り出す\n振り切る己をゆく\nstill alive? ロゴスの誘いは so, still alive? まだ見えない\n汚れてく異教徒たちの涙\n月の下 顔のないマリア | N24: 啊 那曾羞辱我的 你的旋律 如今仍在狂暴肆虐吗？\n \n战栗的大教堂 抗争的心脏\n逐渐燃烧没有后发的福尔图娜\n \nstill alive 生命的齿轮 so, still alive 开始转动\n挣脱桎梏贯彻自我\nstill alive? 逻各斯的诱惑 so, still alive? 仍不可见\n逐渐污浊 异教徒们的眼泪\n \n \n \n[face] so, we got to face this [face] we got to face\n[face] 不断重复 异化 逞强 绝望 不得安宁的灵魂 人究竟为何\n \nstill alive 谁人的齿轮 so, still alive 开始疯狂\n不祥的钟楼鸣响\nstill alive? “应至的世界” so, still alive? 正在渴求\n处刑台上 无穷无尽的牺牲者\n \n \n \nnever die 历史的血河 i never die 穿行而过\n彷徨流浪的 我的十字架\n \n \n \nstill alive 生命的齿轮 so, still alive 开始转动\n挣脱桎梏贯彻自我\nstill alive? 逻各斯的诱惑 so, still alive? 仍不可见\n逐渐污浊 异教徒们的眼泪\n月亮之下 无面的玛利亚 | O24: Completeness | P24: 十字架
... A31: The Whole Blue World | B31: The Whole Blue World | C31: Best Album「Ave Música」 | D31: 2026 | E31: 46190 | F31: images/精选通常.webp | G31: Original | H31: Diggy-MO' | I31: Diggy-MO' • 植木建象(SPAWN Inc.) | J31: Diggy-MO' | K31: Coming Soon… | L31: https://www.bilibili.com/video/BV18LjB6eEYm | M31: 風よ 空よ 海よ 隙間に滑り込め\n星よ 時代（とき）よ 真実（ひかり）よ 眼差しの奥で\n \n燃えゆく命 駆け抜ける短さに\n嘲う世界 闇を暴け\n \nBlue, Blue, Blue World The Whole Blue World\n砕け散ってゆく夢 ぼくら晒されて\n震える夜を越え いま儚く消えた声\n \n \n \n何故に 何故に こんなに届かない 苛立ち\n足りない 足りない 言葉じゃ こんなんじゃ感じない\n \nyour head up... stand up...\n神のいないこの天（そら）\n \nBlue,Blue,Blue World So Cruel World\n立ち向かってゆく ぼくら約束の果て\n美しい夜を越え さあ\n \n \n \n確かなもの探していた 打ちひしがれて\n運命を切り拓け\n受け入れられないものを変えてゆけると\n信じたいのに…信じたいのに…\n信じていたのに\n \n \n \nclose to you\nただ終わりへと向かってゆくだけのその哀しみに\n震える君を抱きしめ\n \n追いかける\nBlue,Blue,Blue World The Whole Blue World\n砕け散ってゆく夢 ぼくらそのままで\n震える夜を越え 嗚呼\nいま | N31: 风啊 天空啊 大海啊 滑入缝隙之中吧\n星啊 时光啊 真实（光）啊 在眼神深处\n \n持续燃烧的生命 在飞驰而过的短暂中\n嗤笑着的世界 揭露黑暗吧\n \nBlue, Blue, Blue World The Whole Blue World\n逐渐破碎的梦 我们暴露其中\n越过颤抖的夜 此刻虚幻消失的声音\n \n \n \n为何 为何 如此无法传达 焦躁\n不够 不够 仅凭语言 这样根本感受不到\n \nyour head up... stand up...\n没有神明的这片天空\n \nBlue, Blue, Blue World So Cruel World\n挺身面对 向我们约定的尽头\n穿越美丽的黑夜 来吧\n \n \n \n寻找着确切之物 却深受打击\n开辟命运吧\n相信能改变无法接受之事\n明明想要相信…明明想要相信…\n明明曾经相信\n \n \n \nclose to you\n在那份只是逐渐走向终结的哀伤中\n抱紧颤抖的你\n \n追逐\nBlue, Blue, Blue World The Whole Blue World\n逐渐破碎的梦 我们就这样 \n越过颤抖的夜晚 啊啊\n此刻 | O31: Ave Música | P31: 蓝世界，姨妈
A32: A Cruel Angel's Thesis | B32: 残酷な天使のテーゼ | C32: Digital Single | D32: 2026 | E32: 46256 | F32: images/残纲.webp | G32: Cover | H32: 及川眠子 | I32: 佐藤英敏 | J32: 植木建象 • 冬真 | L32: https://www.bilibili.com/video/BV1X58m6AENA | M32: 残酷な天使のように 少年よ神話になれ\n蒼い風がいま 胸のドアを叩いても\n私だけをただ見つめて微笑んでるあなた\nそっとふれるもの もとめることに夢中で\n運命さえまだ知らない いたいけな瞳\nだけどいつか気付くでしょう その背中には\n遥か未来めざすための羽根があること\n残酷な天使のテーゼ 窓辺からやがて飛び立つ\nほとばしる熱いパトスで 思い出を裏切るなら\nこの宇宙（そら）を抱いて輝く 少年よ神話になれ\nずっと眠ってる 私の愛の揺りかご\nあなただけが 夢の使者に呼ばれる朝がくる中\n細い首筋を 月あかりが映してる\n世界中の時を止めて 閉じこめたいけど\nもしもふたり逢えたことに 意味があるなら\n私はそう 自由を知るためのバイブル\n残酷な天使のテーゼ 悲しみがそしてはじまる\n抱きしめた命のかたち その夢に目覚めたとき\n誰よりも光を放つ 少年よ 神話になれ\n人は愛をつむぎながら 歴史をつくる\n女神なんてなれないまま 私は生きる\n残酷な天使のテーゼ 窓辺からやがて飛び立つ\nほとばしる熱いパトスで 思い出を裏切るなら\nこの宇宙（そら）を抱いて輝く 少年よ神話になれ | N32: 就像那残酷的天使 少年啊 成为神话吧\n在此刻 苍蓝的风 轻轻敲击着我的心\n但你只凝视我 对我微笑\n指尖的轻触 为之执着 为之痴狂\n连那命运也未曾谋面的 稚嫩双眸\n不过总有一天会发觉 就在你背上\n有那为了前往遥远未来而生的羽翼\n残酷天使的行动纲领 旋即从窗边飞出\n若以那迸发的炽热之情 连回忆也一同背叛\n拥抱宇宙 放射光芒 少年啊 成为神话吧\n我那爱的摇篮 一直在沉睡\n有一个清晨 梦之使者会只将你呼唤\n月光映着你纤细的颈\n我多想停止全世界的时间，将你封存于沉眠之中\n如果说我们两人的相逢 有某种意义\n那么我就是那本这样了解“自由”的圣经\n残酷天使的行动纲领 悲伤自此开始\n紧拥的生命形状 自那梦中醒来时\n放射最耀眼的耀眼光芒 少年啊 变成神话吧\n人类一边编制爱 一边创造历史\n依然不能成为女神的我 就这样生存着\n残酷天使的行动纲领 旋即从窗边飞出\n若以那迸发的炽热之情 连回忆也一同背叛\n拥抱宇宙 放射光芒 少年啊 成为神话吧 | P32: 残纲，eva
A33: Fatal | B33: ファタール | C33: Digital Single | D33: 2026 | E33: 46293 | F33: images/fatal.webp | G33: Cover | H33: キタニタツヤ | I33: キタニタツヤ | J33: 植木建象 • 加藤貴之 | M33: また夢から覚める、濡れた瞼を開ける\n狂おしいほど思い残す、遠い日の無力さを呪う\n身を焼かれるような絶望も糧にはなろうか\n憧れに焦がれるまま燃やし続けている\nキラキラお星様宿したあなたのeyes\nカラカラ渇いて可哀想なlack of 愛？\n全てを孤独から救う眩しい光\n僕にだけ落ちる影はあなたのせい？\n致命的な欠落をくれたね\n身勝手な巨星、狂わされた生\nお願い、声を聞かせて、声を聞かせて\n絡まって歪んでしまった傷さえ\nくれたのはあなただけ、あなただけ\nお願い、僕を見ていて、僕を見ていて\n宿命に刻まれた痛みさえ武器にして\nいつかの後悔すら照らせるように\nあなたがいないと生きていけない\n何もかも捧げてしまってもいい\nあなたの愛がまだ足らない\n欠けたものは何で埋めたらいい？\n致命的、致命的、致命的な愛\n運命的、運命的、運命的なI\n必然的、必然的、必然的な哀\n僕を見ていてね、最愛のファタール！\nキラキラお星様宿したあなたのeyes\nカラカラ渇いて可哀想なlack of 愛？\n遥か彼方から放たれた美しさに\n灼かれた眼、もがれた羽根、創造的堕天\nあらゆる視界をジャック\nその輝きはエゴイスティック\n胸の奥仕舞った感情さえ\n引っ張り出して昇華して\n僕という運命を全部抱きしめていく\nあなたがいないと生きていけない\n眩しさでこの身を照らして欲しい\nあなたの愛がまだ足らない\n夢の中でもらうしかないのに\n致命的、致命的、致命的な愛\n運命的、運命的、運命的なI\n必然的、必然的、必然的な哀\n誰のものでもない、最愛のファタール！\n何度悔やんだだろう\n何度呪っただろう\nどれほどの幸福を注いだとしても\n満たされることのない器\n何度夢見ただろう\n何度願っただろう\n僕の胸で膿み続けている傷を撫でる手を\nこの舞台で足掻くことをやめない\nただ一つのアイに近づきたい\n固く定まったこの宿命\nあの星の光からこぼれた闇\nあなたがいないと生きていけない\n何もかも捧げてしまってもいい\nあなたの愛がまだ足らない\n欠けたものは何で埋めたらいい？\n致命的、致命的、致命的な愛\n運命的、運命的、運命的なI\n必然的、必然的、必然的な哀\n僕を見ていてね、最愛のファタール！\n最愛のファタール | N33: 又再从恶梦中惊醒 硬睁开浸湿的眼睑\n几近令人疯狂的懊悔 咀咒遥远昔日的无力\n连这份宛若烧灼自身的绝望也化为食粮吧\n带着对憧憬的向往不断燃烧自己\n寄宿着闪闪星光的你那eyes\n如饥似渴惹人悲怜的lack of 爱？\n将一切从孤独中拯救的眩目光芒\n只落在我一人身上的阴影是你的错？\n你给予了我致命的缺陷呢\n只顾己私的巨星 脱轨失序的人生\n求求你 让我听听你的声音 让我再听听你的声音\n那些紧缠不清彻底扭曲的伤痕\n为我留下的就只有你，惟独只有你\n求求你 请注视着我 一直注视着我\n甚至连深镂于宿命的悲痛也当作武器\n但愿为曾经的后悔亦耀起一丝光明\n没有你的话我根本活不下去\n即使要献上所有一切我都无所谓\n你予我的爱我还远远不足\n缺口的空虚该用什么来填补？\n致命的、致命的、致命的爱\n命运的、命运的、命运的I\n必然的、必然的、必然的哀\n要一直注视着我呢 我最爱的Fatale！\n寄宿着闪闪星光的你那eyes\n如饥似渴惹人悲怜的lack of 爱？\n被你那从遥远彼方所尽放的美\n烧灼的双瞳 折落的翼羽 创造的堕天\n将眼前视野一切占据夺走\n那道耀眼光辉主张着自我的自负\n甚至连深藏于心底的情感\n亦硬是牵扯出来使其升华\n紧紧拥抱住名为我的命运那所有一切\n没有你的话我根本活不下去\n渴望以你的耀光照亮我的身影\n你予我的爱我还远远不足\n明明只能够在梦中得到\n致命的、致命的、致命的爱\n命运的、命运的、命运的I\n必然的、必然的、必然的哀\n不属于任何一个人 我最爱的Fatale！\n已经悔恨过无数次了吧\n已经咀咒过无数遍了吧\n哪怕注入再多的幸福\n都无法被填满的容器\n已经梦到过无数次了吧\n已经许愿过无数遍了吧\n对我伸出能抚慰 我内心持断溃烂化脓伤口的手\n我绝不会放弃在此舞台上挣扎\n只盼更接近那一道爱的身影\n这既已尘埃落定的宿命\n自那道星光涌溢而出的黑暗\n没有你的话我根本活不下去\n即使要献上所有一切我都无所谓\n你予我的爱我还远远不足\n缺口的空虚该用什么来填补？\n致命的、致命的、致命的爱\n命运的、命运的、命运的I\n必然的、必然的、必然的哀\n要一直注视着我呢 我最爱的Fatale！\n我最爱的Fatale | P33: 推子
A34: A Song Of Romance | B34: A Song Of Romance | C34: Digital Single | D34: 2026 | E34: 46279 | F34: images/神名限定cover.webp | G34: Original | H34: Diggy-MO' | I34: Diggy-MO’ • ÐIK | J34: Diggy-MO’ | K34: Coming Soon… | M34: ざわめく海 哀しい幻\n堕ちるように昇ってゆく愛 still burnin’\n鮮やかな闇を描くこの天(そら)に\nまた わたしの吐息を許すのなら\n巡り巡る星よ\n時代(とき)の波間に来て\n生まれ変わって もういちど\nさあ わたしの傷口にキスをして\nloneliness, loneliness, baby, let me hear you\nso, let me hear you sing ‘A Song Of Romance’\nloneliness, baby, let me hear you\nplease, let me hear you sing ‘A Song Of Romance’\nキスをして さあ 癒して キスをして\n甦れば\n真実に近づけると believe\nまた自由に 自由になれると still dreamin’\n追憶の君を辿れば わたしも同じなの\n理解(わか)ってあげられたはずなのに\n揺れる揺れる星を\nそっと 抱き寄せて\n孤独をただ分け合うように\nそうね きっとみんな寂しいのね\nwho am i…\noh, who am i…\nalienation, emptiness,\nfrom despair to where…\nhappiness, loneliness,\nbeyond, beyond,\n巡り巡る星よ\n時代(とき)の波間に来て\n生まれ変わって もういちど\n君に出逢えたなら\n傷だらけの星を\nそっと 抱き寄せて\n孤独をただ分け合うように\n赤裸々に\n…sing ‘A Song Of Romance’\nloneliness, baby, let me hear you\nplease, let me hear you sing ‘A Song Of Romance’ | N34: 喧嚣翻涌的海 悲伤的幻影\n如坠落般不断升腾的爱 still burnin’\n描绘鲜明黑暗的这片天空中\n若能再次容许我的呼吸\n轮回运转的星啊\n来到时光的波涛间\n重获新生 再一次\n来吧 亲吻我的伤口\nloneliness, loneliness, baby, let me hear you\nso, let me hear you sing ‘A Song Of Romance’\nloneliness, baby, let me hear you\nplease, let me hear you sing ‘A Song Of Romance’\n亲吻我 来吧 治愈我 亲吻我\n若能复苏\n就能接近真实 believe\n就能再次自由 变得自由 still dreamin’\n追寻记忆中的你 我也是一样啊\n明明本应能理解你\n将那摇曳不定的星\n轻轻地拥入怀中\n仿佛只是在彼此分担孤独\n是啊 想必大家都很寂寞\nwho am i…\noh, who am i…\nalienation, emptiness,\nfrom despair to where…\nhappiness, loneliness,\nbeyond, beyond,\n轮回运转的星啊\n来到时光的波涛间\n重获新生 再一次\n若能与你相遇\n将那伤痕累累的星\n轻轻地拥入怀中\n仿佛只是在彼此分担孤独\n无遮无掩地\n…sing ‘A Song Of Romance’\nloneliness, baby, let me hear you\nplease, let me hear you sing ‘A Song Of Romance’ | O34: 神の名を | P34: 浪漫，电影

Sheet song_comments
A1: song_name | B1: comment_text | C1: comment_source | D1: comment_from | E1: comment_date
A2: Georgette Me, Georgette You | B2: 我一边想着，如果能将被戏剧化的情感故事比作白银色的乔其纱（Georgette）来表现就好了，一边写下了这首歌。\n 此外，关于频频登场的“月”，以及其所比喻的对象，我也希望能在各种各样的乐曲中运用它，带来不同的想象。\n 在这首歌里，我尤其像描绘一幅美丽的画作那样，一字一句地精心编织。\n “拒绝之事” “接纳之事” \n 人，在“人生的旋转舞台”上不停地扮演着自己。有时甚至会活成并非自己的另一个人。\n 我也希望能够表达出这样一种内涵：“在内心的某个地方，我们都知道存在着一种无法控制的、引导着我们的命运。”\n 真的非常不可思议，人总是同时兼容着相互矛盾的事物。\n 重要的是“微妙”这一点。也就是说，“细腻到令人害怕”。 \n 作为与以往作品的共同项，我在第二段歌词中也加入了隐约让人联想到宗教背景的语句。\n 随之而来的转折点。\n 在人生的各种意义上，都可以认为在“丧失”之后，才是“真正的开始”。 \n 「あなたが触れたわ この傷口に」\n “是你触碰到了啊 这处伤口” \n 如果将其理解为：各种各样的事情逐渐变得明晰，在不断蔓延的悲伤中逐渐懂得人生。那么，那重重交织闪耀着的光芒同时既是痛苦，而黑暗的深邃则让那光芒绽放出更加耀眼的光彩。\n 这是一首纯粹执着于“语言描写”的歌曲。\n 此外，这首歌在构建与动画不同的“独立性”过程中，也采用了这样一种形式：既表现人拼命延续生命的美，又同时带有可以解读为恋爱中关系性表达的一面。 | C2: Ave Mujica Sound Producer Diggy-MO' Completeness解说 | D2: Diggy-MO' | E2: 45744
A3: Symbol III : Water | B3: 我在副歌的乐句中加入了“波浪”这一意象，它也是司掌水的精灵“温蒂妮”的语源。 将“月亮”与“地球”相对比，以超然达观的视角进行了唯美的刻画，同时，也是因为我想要描绘出一个具有官能美的世界观。\n 我刻意引入了处于对立面的阳性特质“火”，以此来反衬阴性特质“水”的神秘，使其更为深邃、宏大。\n 内容上，\n 最初我构建了一个从“月之使者降临此大地”开始的故事。\n 我将这个“月之使者”设定成了，比如高维度的存在，掌管着阴性宫位～，诸如此类的感觉。\n 对于高次元的存在而言，人类的历史不过是转瞬即逝的一瞬。\n 于是，她俯视着这个地上——即三维的“Human Race”（人类种族），并将自己曾经历过的那些故事，如同追溯种种回忆一般，由她本人作为“讲述者”亲自道来，我是这样设定的。\n 此外，歌词中也包含了很多跨越时代前后的复合元素，例如我运用了克里姆特“爱欲与死亡共存”这种偏近代的艺术概念，或者也融入了塔罗牌牌组所展现的那种联想空间。 通过探索这些不同主题的组合，或许能进一步升华为Ave Mujica式的格调，那便是我的期望。\n 我特意放入“欲望”、“紧张”、或者是“大宇宙”这样直白露骨的词汇，也是出于这一目的。\n 阴性特质将阳性特质包容进去，形成一种宏大的感觉。\n 在表达“两性交融”这一直接含义的同时，另一方面，我也将宗教的根源作为多层面的概念融入其中。\n 阳性宫位之火的“△”与阴性宫位之水的“▽”重合，就会变成“六芒星”的符号，而这正意味着“大宇宙”，因此在第一段副歌中，我试图表达这种宇宙的完满性因果与秩序。\n 而在最后的部分，我的期望是，最终不去描绘那种“大宇宙”般不可估量的宏大事物，而是珍重地描绘活在此刻“生命”中的“最微小的世界”。为了让听众能感受到这一点，我在结尾处忽然将视角拉回，只是从地上仰望这片“天空”。于是，支线故事包含着“生命赞歌”的含义，而我这首歌想要表达的本质依旧是“爱之歌”。 | C3: Ave Mujica Sound Producer Diggy-MO'访谈 & Elements概念解析 | D3: Diggy-MO' | E3: 45567
A4: Sophie | B4: ——「Sophie」是基于怎样的概念开始制作的？\n我想到了“唯物主义”这个概念，所以一边以萨德侯爵的《美德的不幸》为母题（Motif），一边将其投射到Ave Mujica的世界观中。我也引入了情色主义（Eroticism）的要素，截取了原本的人性得到释放、赤裸裸的残酷瞬间。另外，作为暗线主题，我还追溯时代，复合地融合了将诺斯替主义（Gnosticism）的宇宙观、神话及宗教背景等。\n——具体是以怎样的意象进行拓展的呢？\n我认为如果做一些诸如价值观或道德观念瓦解这种彻底崩塌的意象，能够引发出她们与以往不同的魅力。我将其比作现代社会的构图，在不损品格的前提下，引入处于极限边缘的表现形式并使其具象化。其实对我来说，这并不是什么罕见的切入点，但我认为，向一般的音乐受众展示这种表现形式的普遍性，也是一个重要的机会。我将猎奇、无神论等脑海中的意象进行各种组合，以此煽动那种生猛感。\n——钢琴的音色非常优美，请问使用的是什么？如果是软件音源的话请告诉我们音色名称。\n是NATIVE INSTRUMENTS Kontakt的Alicia's Keys。因为挂了几个效果器，所以可能听起来和原本的音色相去甚远。\n——关于弦乐编曲，是从编制开始构建的吗？\n这首歌的编制是以四重奏来组建的。不出所料这部分也是和人声主旋律以及其他乐器的合奏同步制作的。感觉就像是将脑海中听到的旋律和复调（Counter）乐句，在各自通道上用MIDI写成乐谱。因为这个乐队也有钢琴，所以需要一边弹钢琴一边将所有内容包含在内进行编曲。\n——具体的作业是如何进行的呢？\n基本上是先在四重奏的各个通道上制作相互交织的乐句。有时也会像常规手法那样，先在一个通道上把音源设为弦乐整体的组合，一边先决定大概的轮廓，也有这样的情况。在具体区分制作时，虽然令人印象深刻的乐句主要由第一小提琴担任的情况很多，但在一些细小的声部或段落中，当然也有很多情况会让大提琴或中提琴来承担这一角色。这方面我也在仔细斟酌合奏中交织乐句的机能美。我的目标是既能让主唱突显出来，又能留下“弦乐和钢琴很帅气的曲子”这一印象的、行之有效的精心制作。\n——请教一下使用的音源和效果器。\n音源选择了VIENNA SYMPHONIC LIBRARY。在通过编程还原弦乐时，我会仔细选择表情控制、音量写入以及演奏法，来打磨细腻的表现。在效果处理方面，通常管弦乐等的弦乐不会加太多压缩，但在流行乐的情况下，我会使用磁带系的效果器，在不破坏抑扬顿挫的程度内微量增加并进行处理。\n——感觉面向结尾的高潮部分紧紧抓住了人心。你是如何考量并构建这种展开的呢？\n无论创作什么歌曲，我都都会下功夫维持紧张感。我认为这也算是某种关于如何捕捉“意外性”的部分。在这首歌里，因为我认为特别是必须要将紧迫感一直煽动到最后，所以一边计算着主唱人声最终到达的表现境界，一边在最后的一个大段落里整个引入机关，构建出令人提心吊胆的结构。 | C4: Sound ＆ Recording 2026.02 | D4: Diggy-MO' | E4: 46054
A5: Sophie | B5: ──「Sophie」真的是一首只有佐佐木小姐才能驾驭的曲子……总而言之，我感到非常震惊。是一首极其厉害的歌。\n佐佐木：我也从来没有唱过这样的歌。必须全身心投入，以至于在演唱过程中甚至像是失去了记忆，不彻底沉浸进去就唱不出来。当时已经完全进入了心流状态……该怎么形容呢，感觉脑细胞在被逐渐破坏，血管都快要爆裂了一样。根本无法用普通的方式去演唱。\n ──「Sophie」的歌词我最初拜读的时候也受到了极大的冲击，甚至有点不知道该如何去形容。\n佐佐木：真的呢。这是一首只有 Ave Mujica 才能做到的曲子吧。能够被委以重任演唱这样的歌我感到很荣幸，而且乐器部分的编排也非常厉害。一般来说，这种曲子是不会突然让给别人唱的。所以，这也激发了我们“大干一场吧！”的斗志。我非常开心。\n ──刚拿到这首曲子的时候，您最直观的想法是什么？\n佐佐木：首先我觉得“这根本不是在唱歌”。这是呐喊……灵魂的尖叫。但是，我想把这种“尖叫”一直贯彻到最后。毕竟这首曲子传达的就是这样的东西。我在参考Demo的同时，也想唱出自己心中描绘的「Sophie」，所以里面也有我完全改变了原本唱法的部分。比如第2段主歌之后的尖叫。我觉得这里应该可以自由发挥，所以就没有和大家商量直接尝试了一次，结果就被采用了。\n ──是〈material, material,〉那一段对吧。令人印象非常深刻。\n佐佐木：那一段我听都想问“这到底是谁在唱啊”……我的记忆就是缺失到了那种程度。唱歌的时候，我好像在用力抓挠自己的身体，回家的路上觉得身上疼，一看才惊讶地发现满是抓痕。我当时就想，“原来被歌曲附身演唱就是这种感觉啊”（苦笑）。\n ──甚至连这个小插曲都跟这首曲子无比契合呢。我很迷茫，不知道应该怎么说才好，像是被袭击了，但又仿佛是被引诱了……\n佐佐木：是啊。感觉像是在歌唱某种“完全没有道理可言之事”，但也可以理解为在“享受这种不公”。比如那句“真的好讨厌”（ほんとヤダ），到底是不是真的在抗拒呢。\n ──确实是这样。在不断重复〈真的好讨厌〉的过程中，语气和情感也发生了变化，这点也引人深思。\n佐佐木：感觉就像是把那种真实的“动摇”原封不动地塞了进去。我觉得在最后选用的音轨里，也有制作团队刻意保留下来的粗糙、未经修饰的部分。我非常喜欢最后一段副歌里的高音，那里的狂野的爆发力非常棒，还有“引诱我”（誘って）那句稍微残留的换气声，也刻意按原样保留了下来。甚至连叹息声、呜咽声也都原封不动地保留了，希望大家在听的时候也能去享受这些细节。 | C5: https://www.animatetimes.com/news/details.php?id=1765333295&p=3 | D5: 佐佐木李子 | E5: 46002
A6: The Whole Blue World | B6: ——刚才也提到过，作为新曲的「The Whole Blue World」是一首连接了 Ave Mujica 过去与未来的歌曲。 \n佐佐木：是的呢。我觉得 Ave Mujica 给人一种孤高的印象。但是这首歌，感觉像是在歌颂共同坠落的美。看歌词的话，有很多像是“残酷的世界中”、“无法传达的焦躁”、“渐渐粉碎的梦境”、“感受到痛苦”之类的词汇。但在其中，依然有一种“想要切实地触碰你”的感觉。我觉得这部分的氛围和以前稍微有些不同。 歌词中出现了“我们”（僕ら）这个词，也让我印象非常深刻。应该说是一种选择一起受伤害的细腻感吗，其中也还有“明明想要去相信”的纠结和动摇的部分，我非常喜欢。带着这种动摇仍要继续前进的感觉，我觉得非常有 Ave Mujica 的风格。我是绷紧了神经，全神贯注地去演唱这首歌的。\n冈田：我有个单纯的疑问，在录音的时候，你不会“哇——”地一下情绪失控吗？（笑）\n 佐佐木：虽然不会“哇——”地叫出来（笑），但确实有一种自己正在坠入黑暗的感觉。在之前的采访中我也提到过，在唱「Sophie」的时候，回过神来发现手上全是伤痕，我应该是下意识地用力攥紧了手，在“真的好讨厌”“真的好讨厌”（ほんとヤダ）那里。就是这样，贴近着歌词的情感去演唱的。 这首歌也是，感觉像是让内心静静地沸腾起来。我会一边想象着那种包含着心中的焦躁、痛苦和软弱，却依然要继续前行的感觉，一边去演唱。\n——「The Whole Blue World」里的“Blue World”，让人既能感受到清澈的蓝，也能感受到那种仿佛要深深沉沦下去的蓝。\n佐佐木：确实，感觉它不仅仅是一个普通的蓝色世界。在其中既能感觉到充满透明感的蓝，也能感觉到深邃的蓝。非常有Ave Mujica的风格。我觉得Ave Mujica不仅仅是有攻击性，那种细腻而优雅的部分也是 Ave Mujica 的一部分。我认为这首歌是一首能够同时体会到这两面的歌曲。\n 冈田：真是一种不可思议的平衡呢。和声也录制了非常多的版本。Ave Mujica的歌曲，都是由 Diggy-MO' 先生来录制Demo的。听到Diggy-MO'先生的演唱，我们也能明确地明白“这首歌想要呈现出怎样的感觉”。而且，我能听出来李子亲并没有完全仿照，而是很好地将其升华为Doloris的风格来演唱。这点每次都让我很感动。其他的歌曲中，强调沉重感的曲子比较多，但这首歌相对来说，让我感受到了深沉感。\n 佐佐木：我确实是有意识地在表现这种深沉感！而且，也刻意去表现了那种带着冰冷感的蓝。并不是粗暴地去击打，而是那种优美地夺走你呼吸的感觉，你能体会到这一层我真的很高兴。 \n冈田：太棒了！ | C6: https://www.animatetimes.com/news/details.php?id=1781597468&p=2 | D6: 佐佐木李子&冈田梦以
A7: in your blue eyes | B7: 明日方舟 Side Story 「无忧梦呓」 联动曲 | D7: Tie-up
A8: Black Birthday | B8: Debut track | D8: Remark
A9: Two Moons | B9: ——初华和祥子，换句话说也就是 Doloris 和 Oblivionis，在演唱会上也有很多像「双月 ~Deep Into The Forest~」和「Symbol III : ▽」这样成对出现的演出呢。\n高尾：大家也都非常敏锐地感受到了呢。我每次在演唱会上都会想着“请期待动画！”（笑）\n渡濑：初华从动画的先导预告片时期开始，被截取出来的台词就几乎全都和祥子有关呢。我想大家从那个阶段开始，应该就已经察觉到一些端倪了吧（笑）。 | C9: https://www.lisani.jp/0000274367/4/?show_more=1 | D9: 渡濑结月&高尾奏音
A10: Choir 'S' Choir | B10: 我觉得比较棘手的一首歌是「Choir ‘S’ Choir」。在大家都在踩正拍节奏的时候，唯独贝斯走的是反拍。此外，由于曲速很快、乐句也很细密，实际上在曲子中，我需要不断切换使用下拨和交替拨弦。虽然像这样极具挑战性的曲子有很多，但弹奏「Ave Mujica」总之就是非常开心（笑）。尤其喜欢变成三拍子那一段的乐句。 | C10: https://www.oricon.co.jp/news/2294611/full/ | D10: 冈田梦以
A11: Choir 'S' Choir | B11: ——接下来请谈谈迷你专辑「Alea jacta est」。这张专辑收录了以重型乐器编排打造的硬核金属音效为主轴的共6首歌曲，能请各位说说各自最推的歌曲吗？\n 渡濑：刚才我们也稍微聊到了推的歌曲，当时めいしゃん（冈田）提到的「Choir ‘S’ Choir」我也很喜欢。虽然还不能详细透露，其实Ave Mujica的每首歌都有各自的主题元素（Theme），在看到0th LIVE的演出时，我发现这首歌正是沿着那个主题展开的，就觉得“就是这个！”而感觉很感动。从那以后一下子就喜欢上了。\n 佐佐木：我录音的时候也被告知了每首歌的母题（Motif），是注意着那种意象和世界观去演唱的。歌词里，Diggy-MO’先生独特的措辞和故事之中，也散落着与那个主题相关的关键词，希望大家一定要去考察解读。\n 渡濑：めいしゃん为什么最推「Choir ‘S’ Choir」？\n 冈田：因为这首的贝斯在原创曲里是最难的，跟它较劲的时间也比较长，还有就是我在这首歌里很喜欢李子酱的演唱。我觉得她对声音的运用以及演唱技巧的储备极其丰富，比如还加入了一点嘶吼式的唱法。\n 佐佐木：诶——好开心！不过「Choir ‘S’ Choir」里大家的和声也很多，所以完成得非常华丽呢。\n 冈田：のんたん（高尾）的念白也很棒。\n 高尾：谢谢！其他还有「Mas?uerade Rhapsody Re?uest」里也有念白，祥子在歌曲里就会突然开始说英语（笑）。而且「Choir ‘S’ Choir」里的rap部分还是拉丁语。还有，这个可能谁都没有注意到，在「神さま、バカ」副歌结尾的“神さま、バカ”那里，用耳语声加入了一句“神さま、バカ”的念白，其实那也是我（笑）。\n （中略）\n 米泽：我也推「Choir ‘S’ Choir」。除此之外，「Ave Mujica」是我们最早拿到的歌曲，单纯是听得最多的一首，而且乐队名直接就是歌名，所以觉得这是很能代表我们的歌，感情很深。 | C11: https://www.animatetimes.com/news/details.php?id=1711341820&p=3 | D11: 全员
A12: Choir 'S' Choir | B12: 高尾：（笑）。比如说，「Choir ‘S’ Choir」的话，就是想象着在草原上弹奏的感觉。我会在自己心里变换场景意象来演奏，所以刚才被你说中，吓了一跳。\n 佐佐木：我一直都感觉得到哦！\n 高尾：好厉害！我们心意相通了啊！\n | C12: https://www.animatetimes.com/news/details.php?id=1711341820&p=3 | D12: 佐佐木李子&高尾奏音
A13: Black Birthday | B13: ——感觉还能通宵畅聊呢（笑）。那么，如果要选一首特别有感情的乐曲的话？\n 高尾：真的很难选……我可能会选「黒のバースデイ」。因为它是0th LIVE上第一首演奏的歌曲，演奏的时候会有一种瞬间回到那个时候的感觉。或者说，能让我找回初心。\n 米泽：我懂！有一种穿着黑袍的感觉。\n 渡濑：确实（笑）。对观众来说，如果要说Ave Mujica的代表曲可能会想到「Ave Mujica」，但对我们来说，「黒のバースデイ」才是真正开始的曲子。最早练习的也是这首歌。\n 佐佐木：而且，它也是一首仿佛在为 Mujica 的诞生送上祝福的歌曲。\n | C13: https://www.lisani.jp/0000271996/2/?show_more=1 | D13: 全员
A14: Memento Mori | B14: 高尾：……还有，这个可能谁都没有注意到，在「神さま、バカ」副歌结尾的“神さま、バカ”那里，用耳语声加入了一句“神さま、バカ”的念白，其实那也是我（笑）。\n 佐佐木：这段声音重叠的地方，真的超级戳人\n 高尾：我主推的曲子就是这首「神さま、バカ」，我觉得李子酱的表现力太厉害了！在伴奏安静下来的那段副歌里，是从钢琴独奏过渡到李子酱的歌声。在演唱会或彩排演奏的时候，我一直都是怀着“希望能配合李子酱歌声的抑扬顿挫来弹奏”的想法去练习的。\n 佐佐木：诶——！我正好相反，是一边被弄碳那听起来仿佛快要哭出来的琴音所感染，一边唱出来的哦。\n 高尾：是这样吗？那原来我们一直都是在互相感受着彼此、互相配合着在演奏的呢（笑） | C14: https://www.lisani.jp/0000239390/2/?show_more=1 | D14: 佐佐木李子&高尾奏音①
A15: Memento Mori | B15: ——请用一句话，向大家推荐一下这张迷你专辑的必听之处吧。\n 【高尾】 我在录音时第一次听到那段演唱，就被那种惊人的表现力深深感动了。另外，「神さま、バカ」这首歌也非常棒。在演唱会上弹奏时，我的内心也一直被那歌声所震撼着，所以请大家务必去看看Live的影像，亲自感受一下。 | C15: https://www.oricon.co.jp/news/2294796/full/ | D15: 高尾奏音①
A16: Memento Mori | B16: ——这种羁绊是从什么时候开始感受到的呢？\n 高尾：（看着佐佐木）你觉得是从什么时候开始的？\n 佐佐木：不知为何，我们从一开始关系就很好呢（笑）。 \n高尾：真的是那种“回过神来就……”的感觉。虽然李子亲（佐佐木）是稍微晚一点才加入进来的。\n 佐佐木：让我加入到四个已经打成一片的人当中，一开始真的非常不安……。我也是第一次正儿八经地组乐队，所以事前做了功课去调查“她们都是些什么样的孩子呢？”。\n 高尾：她还在笔记本上把大家的个人资料都写了下来呢。 \n——好厉害！ \n佐佐木：是的。因为实在太期待了。\n 高尾：从我们的角度来看，就会觉得“这么完美契合Ave Mujica中心位置的女孩子只能是李子亲啊！”虽然平时在歌里唱着“神啊，愚蠢”，但心里想的其实是“感谢神明让李子亲来当我们的主唱！”\n 佐佐木：好开心！ | C16: https://www.animatetimes.com/news/details.php?id=1711341102&p=2 | D16: 佐佐木李子&高尾奏音②
A17: Memento Mori | B17: ——以 Ave Mujica 的音乐性来看，嘶吼（Shout）或者死嗓（Growl）等唱法作为其中一种选择也是完全有可能的吧。\n 【佐佐木】我看着成员们的身影时，就会强烈地觉得，这支乐队能成为超越常规的存在。嘶吼也是一种选择，还有比如在「神さま、バカ」这首歌里尝试吊威亚飞天之类的……我连这种天马行空的舞台演出都在幻想着（笑）。在以“Ave Mujica的风格”为大前提的基础上，我想不给自己设限，一边享受一边去创造。 | C17: Ave Mujica、以“不自我设限”的姿态，引领前往“未曾有过的世界” | D17: 佐佐木李子
A18: Memento Mori | B18: ——然后到了2025年，以TV动画『BanG Dream! Ave Mujica』的播出为开端，势不可挡的“Mujica之年”即将拉开帷幕。\n 高尾： 信息量实在是太大了，看一遍根本消化不完呢。我觉得哪怕是至今为止已经发行过的那些歌曲，在看了动画之后，大家对它们的理解和感受也会发生改变。就我个人而言，非常希望大家能在看完动画全篇之后，再去重新听一遍「神さま、バカ」。 | C18: https://www.lisani.jp/0000271996/4/?show_more=1 | D18: 全员②
A19: Mas?uerade Rhapsody Re?uest | B19: ——那「Mas?uerade Rhapsody Re?uest」这首歌呢？\n 冈田：我非常喜欢这种快节奏的歌。而且里面甩头的部分也特别好玩。 \n高尾：甩头确实很好。\n 冈田：感觉粉丝们也一直很期待我们开始甩头的那个环节，我很喜欢这点。\n 佐佐木：之前在 Roselia 的LIVE热场表演这首歌时，我中途停下了甩头，以Doloris的姿态俯视着台下的观众，心里想着“你们也给我甩起来”。真的感觉到了会场合为一体。\n 冈田：这是一首非常适合我们在LIVE上展示演奏魅力的曲子。 | C19: 月刊武士道 2024年2月号 Ave Mujica访谈 | D19: 全员
A20: Mas?uerade Rhapsody Re?uest | B20: ——包括至今为止录制过的歌曲，在录音指导的过程中，有没有哪些瞬间让您获得了新的感悟呢？\n 【佐佐木】 这或许和“感悟”有些不太一样，但「Mas?uerade Rhapsody Re?uest」的录音过程让我印象极深。这首歌在录制完毕、大家正在确认录音音轨的时候，我自己本来也觉得“我已经毫无保留地发挥到极致了”。但是，制作人当时向我提议：“要不要最后再试着唱一遍？”，而我最后榨干所有力气唱出的那个版本，最终被正式采用了。那一刻，我深切地感受到，“Ave Mujica 的乐曲竟然能如此拓宽我自身的可能性”、“说不定我还能突破更多极限呢……” | C20: Ave Mujica、以“不自我设限”的姿态，引领前往“未曾有过的世界” | D20: 佐佐木李子
... A31: Angles | B31: ——虽然不是本作的收录曲，但我感觉「Angles」这首歌中“don't be serious”这句歌词非常具有 Diggy先生的个人风格。在 Ave Mujica 这样具有黑暗世界观的乐队歌词中，编织出带有“放轻松”“别太当真”这种含义的词句，非常有趣。\n 佐佐木：确实会有很多这种“居然在这里用这个词！”的惊喜。我在演唱前，总是会随身带着一本手抄歌词的笔记本。我会查词语的意思，也会把英语的意思写上去……。另外，Diggy 先生有时候会指定换气的位置，一开始我并没有完全理解其中的意图，但在不断练习的过程中，我才发现如果在那个位置换气，听起来会像是在哭泣一样。比如在本作中，「Symbol III : ▽」等歌曲就是这样。我在唱我的solo曲的时候也一定会记笔记，但是写下这么多的笔记，Ave Mujica 还是头一次。关于 Ave Mujica 成员们的情报、以及在 Live 上注意到的事情等等，我也全都记在上面了。 | C31: https://natalie.mu/music/pp/avemujica01/page/2 | D31: 佐佐木李子②
